Workbook
Name baseline: NA()
Name DD: "#REF!"
Name rpt_date: NA()
Name T01_컬럼정보_Query: "#REF!"
Name tol: NA()
Name ㄴ: "#REF!"
Name ㅇㅇ: NA()

Sheet 표지
M4: WMS 구축 프로젝트
M7: 인터페이스설계서

Sheet 개정이력
A1: 개 정 이 력
A3: 버전 | B3: 개정범위 | C3: 내용 | D3: 작성자 | E3: 일자
A4: v1.0 | B4: 전체 | C4: 최초 작성 | D4: 이택 | E4: 2026.01.01

Sheet 센터정보
A1: * 센터정보 | F1: 2026.01.01
A2: NO | B2: WMS 센터 | D2: ERP창고 | F2: 비고
B3: 센터명 | C3: 코드 | D3: 창고명 | E3: 코드
A4: 1 | B4: 수도권센터 | C4: 1 | D4: 수도권창고 | E4: A1000
A5: 2 | B5: 김포센터 | C5: 2 | D5: 김포창고 | E5: E1000
A6: 3 | B6: 동부센터 | C6: 3 | D6: 동부창고 | E6: B1000
A7: 4 | B7: 남부센터 | C7: 4 | D7: 남부창고 | E7: D1000
A8: 5 | B8: 서부센터 | C8: 5 | D8: 서부창고 | E8: C1000
A9: 6 | B9: 강원클러스터 | C9: 6 | D9: 강원창고(직영) | E9: G2004
A10: 7 | B10: 익산클러스터 | C10: 7 | D10: 익산창고 | E10: F1000
A11: 8 | B11: 제주클러스터 | C11: 8 | D11: 제주창고 | E11: G4003
A12: 9 | B12: 외주센터1 | C12: 9 | E12: H1001 | F12: 지오컴퍼니
A13: 10 | B13: 외주센터2 | C13: 10 | F13: 이지그린
A14: 11 | B14: 외주센터3 | C14: 11 | F14: 업체 3원화시 사용
A15: 12 | B15: 외주센터4 | C15: 12 | F15: 에스엠피엔씨
A16: 합계 | B16: =COUNTA(B4:B15) -> 12

Sheet ERP_인터페이스목록
A1: =CONCATENATE("인터페이스 목록 (총 ", MAX(A2:A12335), "개)") -> 인터페이스 목록 (총 26개)
A2: No | B2: 업무 | C2: 항목 | D2: 송신 시스템 | E2: 수신 시스템 | F2: IF 코드 | G2: WMS IF ID | H2: IF 처리내용 | I2: WMS IF명 | J2: IF URL (테스트서버) | K2: IF URL (운영서버) | L2: API 방식
A3: 1 | B3: 공통 | C3: API KEY 발행 | D3: OMS | E3: WMS | F3: APK_KEY | G3: =CONCATENATE(LEFT(D3,1),2,LEFT(E3,1),"_",F3) -> O2W_APK_KEY | H3: IF 시 필요한 API KEY 발급 | I3: =C3 -> API KEY 발행 | J3: /{bizSeq}/sif/wms/apikey | L3: POST
A4: 2 | B4: 기준정보 | C4: 품목 등록 | D4: ERP | E4: WMS | F4: PROD_REG | G4: =CONCATENATE(LEFT(D4,1),2,LEFT(E4,1),"_",F4) -> E2W_PROD_REG | H4: 품목 신규 등록 및 품목 데이터 수정 | I4: =C4 -> 품목 등록 | L4: DB to DB
A5: 3 | C5: 거래처 등록 | D5: ERP | E5: WMS | F5: CONT_REG | G5: =CONCATENATE(LEFT(D5,1),2,LEFT(E5,1),"_",F5) -> E2W_CONT_REG | H5: 거래처 신규 등록 및 거래처 데이터 수정 | I5: =C5 -> 거래처 등록 | L5: DB to DB
A6: 4 | C6: 사번체크 | D6: WMS | E6: ERP | F6: EMP_CHK | G6: =CONCATENATE(LEFT(D6,1),2,LEFT(E6,1),"_",F6) -> W2E_EMP_CHK | H6: ERP 사번 유/무 체크 | I6: =C6 -> 사번체크 | L6: DB to DB
A7: 5 | B7: 입고 | C7: 입고예정 등록 | D7: ERP | E7: WMS | F7: IW_PO_REG | G7: =CONCATENATE(LEFT(D7,1),2,LEFT(E7,1),"_",F7) -> E2W_IW_PO_REG | H7: 입고예정 신규 등록 및 입고예정 데이터 수정 | I7: =C7 -> 입고예정 등록 | L7: DB to DB
A8: 6 | C8: 예외입고_등록 | D8: ERP | E8: WMS | F8: IW_STO_REG | G8: =CONCATENATE(LEFT(D8,1),2,LEFT(E8,1),"_",F8) -> E2W_IW_STO_REG | H8: 예외입고 신규 등록 및 예외입고 데이터 수정 | I8: =C8 -> 예외입고_등록 | L8: DB to DB
A9: 7 | C9: 입고마감 | D9: WMS | E9: ERP | F9: IW_PO_CFM | G9: =CONCATENATE(LEFT(D9,1),2,LEFT(E9,1),"_",F9) -> W2E_IW_PO_CFM | H9: 입고 마감 결과 전송 | I9: =C9 -> 입고마감 | L9: DB to DB
A10: 8 | B10: 반품 | C10: 반품예정 등록 | D10: OMS | E10: WMS | F10: RT_REG | G10: =CONCATENATE(LEFT(D10,1),2,LEFT(E10,1),"_",F10) -> O2W_RT_REG | H10: 반품예정 신규 등록 및 반품예정 데이터 수정 | I10: =C10 -> 반품예정 등록 | J10: /{bizSeq}/sif/rtrq01/regs | L10: POST
A11: 9 | C11: 반품마감_ERP | D11: WMS | E11: ERP | F11: RT_CFM | G11: =CONCATENATE(LEFT(D11,1),2,LEFT(E11,1),"_",F11) -> W2E_RT_CFM | H11: 반품 마감 결과 전송(ERP) | I11: =C11 -> 반품마감_ERP | L11: DB to DB
A12: 10 | C12: 반품마감_OMS | D12: WMS | E12: OMS | F12: RT_CFM | G12: =CONCATENATE(LEFT(D12,1),2,LEFT(E12,1),"_",F12) -> W2O_RT_CFM | H12: 반품 마감 결과 전송(OMS) | I12: =C12 -> 반품마감_OMS | J12: /{bizSeq}/sif/w2o/rt/cfm | L12: POST
A13: 11 | B13: 예외 | C13: 예외출고 등록 | D13: ERP | E13: WMS | F13: EX_STO_REG | G13: =CONCATENATE(LEFT(D13,1),2,LEFT(E13,1),"_",F13) -> E2W_EX_STO_REG | H13: 예외출고(계정대체출고) 신규 등록 및 예외출고(계정대체출고) 데이터 수정 | I13: =C13 -> 예외출고 등록 | L13: DB to DB
A14: 12 | C14: 예외출고 마감 | D14: WMS | E14: ERP | F14: EX_STO_CFM | G14: =CONCATENATE(LEFT(D14,1),2,LEFT(E14,1),"_",F14) -> W2E_EX_STO_CFM | H14: 예외출고(계정대체출고) 처리 결과 전송 | I14: =C14 -> 예외출고 마감 | L14: DB to DB
A15: 13 | B15: 출하 | C15: 출하예정 등록(판매출하) | D15: OMS | E15: WMS | F15: OB_SO_REG | G15: =CONCATENATE(LEFT(D15,1),2,LEFT(E15,1),"_",F15) -> O2W_OB_SO_REG | H15: 출하예정 신규 등록 및 출하예정 데이터 수정(판매출하/외주직출) | I15: =C15 -> 출하예정 등록(판매출하) | J15: /{bizSeq}/sif/obrq01/regs | L15: POST
A16: 14 | C16: 출하예정 등록(마감후출하) | D16: WMS | E16: OMS | F16: OB_CLO_REG | G16: =CONCATENATE(LEFT(D16,1),2,LEFT(E16,1),"_",F16) -> W2O_OB_CLO_REG | H16: 출하예정 신규 등록 및 출하예정 데이터 수정(마감후출하) | I16: =C16 -> 출하예정 등록(마감후출하) | J16: /{bizSeq}/sif/w2o/add/so/pull | L16: POST
A17: 15 | C17: 출하예정 등록(삭제오더) | D17: OMS | E17: WMS | F17: OB_CLE_REG | G17: =CONCATENATE(LEFT(D17,1),2,LEFT(E17,1),"_",F17) -> O2W_OB_CLE_REG | H17: 출하예정 신규 등록 및 출하예정 데이터 수정(삭제오더) | I17: =C17 -> 출하예정 등록(삭제오더) | J17: /{bizSeq}/sif/delo01/regs | L17: POST
A18: 16 | C18: 출하예정 삭제(판매출하) | D18: OMS | E18: WMS | F18: OB_SO_DEL | G18: =CONCATENATE(LEFT(D18,1),2,LEFT(E18,1),"_",F18) -> O2W_OB_SO_DEL | H18: 출하예정 삭제(판매출하) | I18: =C18 -> 출하예정 삭제(판매출하) | J18: /{bizSeq}/sif/obrq01/dels | L18: POST
A19: 17 | C19: 출하예정 삭제(삭제오더) | D19: OMS | E19: WMS | F19: OB_CLE_DEL | G19: =CONCATENATE(LEFT(D19,1),2,LEFT(E19,1),"_",F19) -> O2W_OB_CLE_DEL | H19: 출하예정 삭제(삭제오더) | I19: =C19 -> 출하예정 삭제(삭제오더) | J19: /{bizSeq}/sif/delo01/dels | L19: POST
A20: 18 | C20: 출하 상태변경 | D20: WMS | E20: OMS | F20: OB_STS_CHG | G20: =CONCATENATE(LEFT(D20,1),2,LEFT(E20,1),"_",F20) -> W2O_OB_STS_CHG | H20: 출하예정 상태변경 사항 전송 | I20: =C20 -> 출하 상태변경 | J20: /{bizSeq}/sif/w2o/so/sts/chg | L20: POST
A21: 19 | C21: 마감 후 출하승인 결과 | D21: WMS | E21: OMS | F21: OB_CLO_ODR | G21: =CONCATENATE(LEFT(D21,1),2,LEFT(E21,1),"_",F21) -> W2O_OB_CLO_ODR | H21: 추가 발주 주문건을 승인/거절 처리 결과 전송 | I21: =C21 -> 마감 후 출하승인 결과 | J21: /{bizSeq}/sif/w2o/add/so/appr | L21: POST
A22: 20 | C22: 미출처리 처리결과 | D22: WMS | E22: OMS | F22: OB_NOB_ODR | G22: =CONCATENATE(LEFT(D22,1),2,LEFT(E22,1),"_",F22) -> W2O_OB_NOB_ODR | H22: 미출처리 된 품목 처리 결과 전송 | I22: =C22 -> 미출처리 처리결과 | J22: /{bizSeq}/sif/w2o/so/qty/mod | L22: POST
A23: 21 | C23: 삭제오더 처리결과 | D23: WMS | E23: OMS | F23: OB_CLE_ODR | G23: =CONCATENATE(LEFT(D23,1),2,LEFT(E23,1),"_",F23) -> W2O_OB_CLE_ODR | H23: 삭제오더 처리 결과 전송 | I23: =C23 -> 삭제오더 처리결과 | J23: /{bizSeq}/sif/w2o/cxl/result | L23: POST
A24: 22 | C24: 주문 품목단가수정 | D24: OMS | E24: WMS | F24: OB_PROD_PRICE | G24: =CONCATENATE(LEFT(D24,1),2,LEFT(E24,1),"_",F24) -> O2W_OB_PROD_PRICE | H24: 주문건 품목 단가수정 수신 | I24: =C24 -> 주문 품목단가수정 | J24: /{bizSeq}/sif/prod-price/regs | L24: POST
A25: 23 | C25: 출고지시_배차요청 | D25: WMS | E25: TMS | F25: OB_REG_DELV | G25: =CONCATENATE(LEFT(D25,1),2,LEFT(E25,1),"_",F25) -> W2T_OB_REG_DELV | H25: 배차 요청사항 폴링 | I25: =C25 -> 출고지시_배차요청 | L25: POST
A26: 24 | C26: 출고지시_배차수정 | D26: WMS | E26: TMS | F26: OB_UDP_DELV | G26: =CONCATENATE(LEFT(D26,1),2,LEFT(E26,1),"_",F26) -> W2T_OB_UDP_DELV | H26: 배차 수정사항 폴링 | I26: =C26 -> 출고지시_배차수정 | L26: POST
A27: 25 | C27: 상차처리_배차및상하차결과 | D27: WMS | E27: TMS | F27: OB_PROC_LOD | G27: =CONCATENATE(LEFT(D27,1),2,LEFT(E27,1),"_",F27) -> W2T_OB_PROC_LOD | H27: 상차 처리결과 폴링 | I27: =C27 -> 상차처리_배차및상하차결과 | L27: POST
A28: 26 | C28: 출하처리_마감 | D28: WMS | E28: ERP | F28: OB_CFM | G28: =CONCATENATE(LEFT(D28,1),2,LEFT(E28,1),"_",F28) -> W2E_OB_CFM | H28: 출하 마감 결과 전송 | I28: =C28 -> 출하처리_마감 | L28: DB to DB
A30: 참조 View 목록
A31: No | B31: 업무 | C31: 항목 | D31: 송신 시스템 | E31: 수신 시스템 | F31: IF 코드 | G31: WMS IF ID | H31: IF 처리내용 | I31: WMS IF명 | J31: IF URL (테스트서버) | K31: IF URL (운영서버) | L31: API 방식
A32: 1 | B32: 공통 | C32: 공통코드_ERP | D32: ERP | E32: WMS | F32: VIEW | G32: =CONCATENATE(LEFT(D32,1),2,LEFT(E32,1),"_",F32) -> E2W_VIEW | H32: ERP 공통코드 View | I32: =C32 -> 공통코드_ERP
A33: 2 | B33: 공통 | C33: 품목군_ERP | D33: ERP | E33: WMS | F33: VIEW | G33: =CONCATENATE(LEFT(D33,1),2,LEFT(E33,1),"_",F33) -> E2W_VIEW | H33: ERP 품목군 View | I33: =C33 -> 품목군_ERP
A34: 3 | B34: 공통 | C34: 창고정보_ERP | D34: ERP | E34: WMS | F34: VIEW | G34: =CONCATENATE(LEFT(D34,1),2,LEFT(E34,1),"_",F34) -> E2W_VIEW | H34: ERP 창고정보 View | I34: =C34 -> 창고정보_ERP

Sheet 공통_API_KEY 발행
A1: 목록
B2: IF명 | E2: =ERP_인터페이스목록!C3 -> API KEY 발행 | O2: ifId | R2: =ERP_인터페이스목록!G3 -> O2W_APK_KEY
B3: URI | E3: =ERP_인터페이스목록!J3 -> /{bizSeq}/sif/wms/apikey
B4: HTTP Method | E4: =ERP_인터페이스목록!L3 -> POST | O4: Data Type | R4: JSON
B6: Request
B7: LV | C7: 항목 | K7: 항목명 | O7: Type | Q7: SIZE | S7: KEY | U7: Null | W7: 설명
B8: 1 | C8: bizSeq | K8: 사업장SEQ | O8: number | Q8: 10 | U8: NN | W8: 1: 교촌에프엔비
B9: 1 | C9: userId | K9: 등록자ID | O9: varchar | Q9: 20 | U9: NN | W9: 타시스템ID/WMS사용자 ID
B10: 1 | C10: userNm | K10: 등록자명 | O10: varchar | Q10: 100 | U10: NN | W10: ERP사용자명/WMS사용자명
B12: Response
B13: LV | C13: 항목 | K13: 항목명 | O13: Type | Q13: SIZE | S13: KEY | U13: Null | W13: 설명
B14: 1 | C14: wmsResult | K14: WMS 처리 결과 | O14: varchar | Q14: 20 | U14: NN | W14: OK : 성공, NG : 실패
B15: 1 | C15: wmsMessage | K15: 메세지 | O15: varchar | Q15: 4000 | U15: NN | W15: 에러메세지
B16: 1 | C16: resList | K16: 응답리스트
B17: 2 | D17: result | K17: 처리 여부 | O17: varchar | Q17: 1 | U17: NN | W17: OK : 성공, NG : 실패
B18: 2 | D18: apiKey | K18: API KEY | O18: varchar | Q18: 100 | U18: NN
B19: 2 | D19: apiKeyExpYmd | K19: KEY 유효기한 | O19: varchar | Q19: 8 | U19: NN | W19: 양식: yyyyMMdd
B21: 비고

Sheet 기준_품목 등록_bak
A1: 목록
B2: IF명 | E2: =ERP_인터페이스목록!C4 -> 품목 등록 | O2: ifId | R2: =ERP_인터페이스목록!G4 -> E2W_PROD_REG
B3: URI | E3: =ERP_인터페이스목록!J4 -> 0
B4: HTTP Method | E4: =ERP_인터페이스목록!L4 -> DB to DB | O4: Data Type | R4: JSON
B5: SOURCE | E5: =ERP_인터페이스목록!D4 -> ERP | O5: TARGET | R5: =ERP_인터페이스목록!E4 -> WMS
B7: Request
B8: LV | C8: 항목 | K8: 항목명 | O8: Type | Q8: SIZE | S8: KEY | U8: Null | W8: 설명
B9: 1 | C9: bizSeq | K9: 사업장SEQ | O9: number | Q9: 10 | U9: NN | W9: WMS 회원 가입시 발행된 BIZ_SEQ
B10: 1 | C10: userId | K10: 등록자ID | O10: varchar | Q10: 20 | W10: 타시스템ID/WMS사용자 ID
B11: 1 | C11: reqList | K11: 품목리스트
B12: 2 | D12: ifProdId | K12: IF_품목_ID | O12: varchar | Q12: 50 | S12: O | U12: NN
B13: 2 | D13: prodNo | K13: 품목번호 | O13: varchar | Q13: 30 | U13: NN | W13: 사업장 내에서 유니크한 값
B14: 2 | D14: prodNm | K14: 품목명 | O14: varchar | Q14: 100 | U14: NN
B15: 2 | D15: prodSize | K15: 품목_규격 | O15: varchar | Q15: 100
B16: 2 | D16: prodDivCd | K16: 품목_분류_코드 | O16: varchar | Q16: 50 | U16: NN | W16: 코드
B17: 2 | D17: largeCd | K17: 대분류_코드 | O17: varchar | Q17: 50 | U17: NN | W17: 코드화: '사용자코드'의 '품목_대분류' 참조
B18: 2 | D18: middleCd | K18: 중분류_코드 | O18: varchar | Q18: 50 | U18: NN | W18: 코드화: '사용자코드'의 '품목_중분류' 참조
B19: 2 | D19: smallCd | K19: 소분류_코드 | O19: varchar | Q19: 50 | U19: NN | W19: 코드화: '사용자코드'의 '품목_소분류' 참조
B20: 2 | D20: cfd_cd | K20: 품온구분 | O20: varchar | Q20: 50 | U20: NN
B21: 2 | D21: unitCd | K21: 단위_코드 | O21: varchar | Q21: 50 | U21: NN | W21: 코드
B22: 2 | D22: inQty | K22: 입수량 | O22: number | Q22: 10 | W22: 1
B23: 2 | D23: netWeight | K23: 순중량 | O23: number | Q23: 10
B24: 2 | D24: note | K24: 비고 | O24: varchar | Q24: 1000 | W24: ERP용 비고와 WMS용 비고 분리
B25: 2 | D25: useYn | K25: 사용여부 | O25: char | Q25: 1 | U25: NN | W25: 코드화 : 'N' / 'Y' (기본'Y')
B27: Response
B28: LV | C28: 항목 | K28: 항목명 | O28: Type | Q28: SIZE | S28: KEY | U28: Null | W28: 설명
B29: 1 | C29: wmsResult | K29: WMS 처리 결과 | O29: varchar | Q29: 20 | U29: NN | W29: OK : 성공, NG : 실패
B30: 1 | C30: wmsMessage | K30: 메세지 | O30: varchar | Q30: 4000 | U30: NN | W30: 에러메세지
B31: 1 | C31: resList | K31: 요청리스트
B32: 2 | D32: ifProdId | K32: IF_품목_ID | O32: varchar | Q32: 20 | S32: O | U32: NN | W32: WMS와 외부 프로그램의 유니크 키
B33: 2 | D33: result | K33: 처리 여부 | O33: varchar | Q33: 1 | U33: NN | W33: OK : 성공, NG : 실패
B34: 2 | D34: message | K34: 처리 메시지 | O34: varchar | Q34: 100 | W34: 처리 실패시 실패 사유
B36: 비고
B37: - 품목명-상품명은 동일하게 셋팅 => 상품명 변경 필요 시 WMS에서 변경 - ERP IF 항목 : 품목번호, 품목명, 품목분류, 대/중/소분류, 규격, 단위 - WMS 관리 항목 : 중량, 입수량, 유효기준일수, 임박기준일수, 상품식별코드, 물류식별코드, 묶음수량, 묶음단위명, 가로/세로/높이, 원산지, 브랜드, 품목SKU - 송부용 상품정보에 포함된 데이터: 품목번호, 품목명, 재고단위, 규격, 품목분류(품목군명), 중량, 중량단위, 사용유무, 안전재고, 대/중/소분류코드, 대/중/소분류명, 출하단위, 품온구분, 육계시세적용구분, 부피, 환산중량

Sheet 기준_품목_등록
A2: 인터페이스명 | B2: 품목등록
A3: 인터페이스 개요
A4: 인터페이스 상세 | B4: 1. ERP 연동 (ERP → WMS)
A5: Description | B5: WMS에서 ERP DB 접근하여 데이터 추출 - 품목명-상품명은 동일하게 셋팅 => 상품명 변경 필요 시 WMS에서 변경 - ERP IF 항목 : 품목번호, 품목명, 품목분류, 대/중/소분류, 규격, 단위 - WMS 관리 항목 : 중량, 입수량, 유효기준일수, 임박기준일수, 상품식별코드, 물류식별코드, 묶음수량, 묶음단위명, 가로/세로/높이, 원산지, 브랜드, 품목SKU - 송부용 상품정보에 포함된 데이터: 품목번호, 품목명, 재고단위, 규격, 품목분류(품목군명), 중량, 중량단위, 사용유무, 안전재고, 대/중/소분류코드, 대/중/소분류명, 출하단위, 품온구분, 육계시세적용구분, 부피, 환산중량
A9: 인터페이스 유형 | I9: 적용방식 | J9: DB2DB
A10: 발생주기 | I10: 1일 발생 건수
A11: SOURCE | I11: TARGET
A12: 시스템 | B12: ERP | I12: 시스템 | J12: WMS
A13: INPUT | I13: INPUT
A14: Table Name | B14: Field | C14: Data Type | D14: PK | E14: Null | F14: Default Value | G14: Description | H14: 비고 | I14: Table Name | J14: Field | K14: Data Type | L14: PK | M14: Null | N14: Default Value | O14: Description | P14: 비고
A15: MA_Z_KCFNB_PITEM_IF | B15: Seq | C15: BIGINT | D15: PK | E15: NN | G15: 생성순번(IDENTITY) | H15: 단순 숫자채번, MAX+1
A16: MA_Z_KCFNB_PITEM_IF | B16: AUDType | C16: CHAR(1) | E16: NN | G16: 신규,수정/삭제 (A/D)
A17: MA_Z_KCFNB_PITEM_IF | B17: CrtDateTime | C17: DATETIME | E17: NN | G17: 생성일시
A18: MA_Z_KCFNB_PITEM_IF | B18: RecvYn | C18: CHAR(1) | F18: N | G18: 수신여부 (Y/N/E) | H18: WMS 미수신 = N WMS 수신 = Y 에러 = E
A19: MA_Z_KCFNB_PITEM_IF | B19: RecvDateTime | C19: DATETIME | G19: 수신일시 | H19: WMS 데이터 수신 후 datetime UPDATE
A20: MA_Z_KCFNB_PITEM_IF | B20: RecvYn_OMS | C20: CHAR(1) | F20: N | G20: 수신여부 (Y/N/E) | H20: WMS 미수신 = N WMS 수신 = Y 에러 = E
A21: MA_Z_KCFNB_PITEM_IF | B21: RecvDateTime_OMS | C21: DATETIME | G21: 수신일시 | H21: OMS 데이터 수신 후 datetime UPDATE
A22: MA_Z_KCFNB_PITEM_IF | B22: BizSeq | C22: INT | E22: NN | F22: 1 | G22: 사업장 SEQ | H22: 1: 교촌에프앤비 | I22: MDM_BIZ_PROD | J22: biz_seq | K22: INT
A23: MA_Z_KCFNB_PITEM_IF | B23: sif_err_msg | C23: TEXT | G23: 에러메세지
A24: MA_Z_KCFNB_PITEM_IF | B24: reg_id | C24: VARCHAR(20) | E24: NN | G24: 등록자ID | H24: 최초 등록자(사용자I/F 의 UserID) | I24: MDM_PROD | J24: reg_id | K24: VARCHAR(20)
A25: MA_Z_KCFNB_PITEM_IF | B25: reg_dt | C25: DATETIME | E25: NN | G25: 등록일 | H25: 최초 등록일시 | I25: MDM_PROD | J25: reg_dt | K25: DATETIME
A26: MA_Z_KCFNB_PITEM_IF | B26: mod_id | C26: VARCHAR(20) | G26: 수정자ID | H26: 데이터 최종수정자(사용자I/F 의 UserID) | I26: MDM_PROD | J26: mod_id | K26: VARCHAR(20)
A27: MA_Z_KCFNB_PITEM_IF | B27: mod_dt | C27: DATETIME | G27: 수정일 | H27: 데이터 최종수정일시 | I27: MDM_PROD | J27: mod_dt | K27: DATETIME
A28: MA_Z_KCFNB_PITEM_IF | B28: CD_COMPANY | C28: NVARCHAR(7) | D28: PK | E28: NN | F28: 1000 | G28: 회사코드 | J28: - | P28: WMS 관리 X
A29: MA_Z_KCFNB_PITEM_IF | B29: CD_PLANT | C29: NVARCHAR(7) | D29: PK | E29: NN | F29: 1000 | G29: 공장코드 | J29: - | P29: WMS 관리 X
I30: MDM_PROD | J30: if_prod_id | K30: VARCHAR(50) | L30: PK | M30: NN | O30: IF_품목_ID | P30: ERP(품목코드:CD_ITEM)로 대체
A31: MA_Z_KCFNB_PITEM_IF | B31: CD_ITEM | C31: NVARCHAR(50) | D31: PK | E31: NN | G31: 품목코드 | H31: 사업장 내에서 유니크한 값 | I31: MDM_PROD | J31: prod_no | K31: VARCHAR(50) | M31: NN | O31: 품목번호
A32: MA_Z_KCFNB_PITEM_IF | B32: NM_ITEM | C32: VARCHAR(200) | E32: NN | G32: 품목명 | I32: MDM_PROD | J32: prod_nm | K32: VARCHAR(200) | M32: NN | O32: 품목명
A33: MA_Z_KCFNB_PITEM_IF | B33: CLS_ITEM | C33: NVARCHAR(3) | G33: 계정구분 | H33: 공통코드 MA_B000010 (원자재,부자재,제품,상품,소모품 등) | J33: - | P33: WMS 관리 X
A34: MA_Z_KCFNB_PITEM_IF | B34: TP_ITEM | C34: NVARCHAR(3) | G34: 품목타입 | H34: 공통코드 MA_B000011 일반품/SET품 구분 | J34: - | P34: WMS 관리 X
A35: MA_Z_KCFNB_PITEM_IF | B35: UNIT_IM | C35: NVARCHAR(3) | G35: 재고단위 | H35: 공통코드 MA_B000004 ex:묶음,CAN,PAC | I35: MDM_PROD | J35: unit_cd | K35: VARCHAR(50) | M35: NN | O35: 단위_코드
A36: MA_Z_KCFNB_PITEM_IF | B36: GRP_ITEM | C36: NVARCHAR(20) | G36: 품목군 | H36: ERP 품목군코드(A:원자재(계육),B:부자재,M:수제맥주) '품목군' 시트 참조 | I36: MDM_PROD | J36: prod_div_cd | K36: VARCHAR(50) | M36: NN | O36: 품목_분류_코드 | P36: X:비정형 품목군은 WMS에서 관리
A37: MA_Z_KCFNB_PITEM_IF | B37: STND_ITEM | C37: NVARCHAR(200) | G37: 규격 | I37: MDM_PROD | J37: prod_size | K37: VARCHAR(200) | O37: 품목_규격
A38: MA_Z_KCFNB_PITEM_IF | B38: BARCODE | C38: NVARCHAR(20) | G38: 바코드 | H38: 88코드 용도(맥주 사용중) | I38: MDM_PROD | J38: prod_barcode | K38: VARCHAR(100) | O38: 품목_바코드(88코드)
A39: MA_Z_KCFNB_PITEM_IF | B39: CLS_L | C39: NVARCHAR(4) | G39: 대분류 | H39: 공통코드 MA_B000030 | I39: MDM_PROD | J39: large_cd | K39: VARCHAR(50) | M39: NN | O39: 대분류_코드
A40: MA_Z_KCFNB_PITEM_IF | B40: CLS_M | C40: NVARCHAR(4) | G40: 중분류 | H40: 공통코드 MA_B000031 | I40: MDM_PROD | J40: middle_cd | K40: VARCHAR(50) | M40: NN | O40: 중분류_코드
A41: MA_Z_KCFNB_PITEM_IF | B41: CLS_S | C41: NVARCHAR(4) | G41: 소분류 | H41: 공통코드 MA_B000032 | I41: MDM_PROD | J41: small_cd | K41: VARCHAR(50) | M41: NN | O41: 소분류_코드
A42: MA_Z_KCFNB_PITEM_IF | B42: FG_TAX_PU | C42: NVARCHAR(4) | G42: 매입부가세 | H42: 공통코드 MA_B000046 부가세율 계산 위함 | J42: - | P42: WMS 관리 X
A43: MA_Z_KCFNB_PITEM_IF | B43: FG_TAX_SA | C43: NVARCHAR(4) | G43: 매출부가세 | H43: 공통코드 MA_B000040 부가세율 계산 위함 | J43: - | P43: WMS 관리 X
A44: MA_Z_KCFNB_PITEM_IF | B44: STND_DETAIL_ITEM | C44: NVARCHAR(200) | G44: 세부규격 | H44: 88코드+주류코드(맥주사용중) | I44: MDM_PROD | J44: prod_size_dtl | K44: VARCHAR(200) | O44: 주류코드 때문에 필요? 88코드 + 주류코드 | P44: 신규컬럼 추가 필요
...

Sheet 기준_거래처 등록_bak
A1: 목록
B2: IF명 | E2: =ERP_인터페이스목록!C5 -> 거래처 등록 | O2: ifId | R2: =ERP_인터페이스목록!G5 -> E2W_CONT_REG
B3: URI | E3: =ERP_인터페이스목록!J5 -> 0
B4: HTTP Method | E4: =ERP_인터페이스목록!L5 -> DB to DB | O4: Data Type | R4: JSON
B5: SOURCE | E5: =ERP_인터페이스목록!D5 -> ERP | O5: TARGET | R5: =ERP_인터페이스목록!E5 -> WMS
B7: Request
B8: LV | C8: 항목 | K8: 항목명 | O8: Type | Q8: SIZE | S8: KEY | U8: Null | W8: 설명
B9: 1 | C9: bizSeq | K9: 사업장SEQ | O9: number | Q9: 10 | U9: NN | W9: WMS 회원 가입시 발행된 BIZ_SEQ
B10: 1 | C10: userId | K10: 등록자ID | O10: varchar | Q10: 20 | W10: 타시스템ID/WMS사용자 ID
B11: 1 | C11: reqList | K11: 거래처 목록
B12: 2 | D12: ifContId | K12: IF_거래처_ID | O12: varchar | Q12: 50 | S12: O | U12: NN
B13: 2 | D13: contNo | K13: 거래처_번호 | L13: 거래처_번호 | M13: 거래처_번호 | N13: 거래처_번호 | O13: varchar | Q13: 30 | U13: NN
B14: 2 | D14: contNm | K14: 거래처_명 | L14: 거래처_명 | M14: 거래처_명 | N14: 거래처_명 | O14: varchar | Q14: 100 | U14: NN
B15: 2 | D15: contDivCd | K15: 거래처_구분코드 | O15: varchar | Q15: 50 | U15: NN | W15: 코드화: 1(매입) / 2(매출) /3(매입/매출) /9(기타)
B16: 2 | D16: ceoNm | K16: 대표자_명 | L16: 대표자_명 | M16: 대표자_명 | N16: 대표자_명 | O16: varchar | Q16: 100
B17: 2 | D17: bizNo | K17: 사업자_번호 | L17: 사업자_번호 | M17: 사업자_번호 | N17: 사업자_번호 | O17: varchar | Q17: 20
B18: 2 | D18: contType | K18: 업태 | L18: 업태 | M18: 업태 | N18: 업태 | O18: varchar | Q18: 100 | W18: 명칭
B19: 2 | D19: contItem | K19: 종목 | L19: 종목 | M19: 종목 | N19: 종목 | O19: varchar | Q19: 100 | W19: 명칭
B20: 2 | D20: center | K20: 센터 | O20: varchar | Q20: 20 | W20: 코드화:
B21: 2 | D21: region | K21: 권역 | O21: varchar | Q21: 20 | W21: 코드화:
B22: 2 | D22: car | K22: 호차 | O22: varchar | Q22: 20 | W22: 코드화:
B23: 2 | D23: warehouse | K23: 외주창고 | O23: varchar | Q23: 20 | W23: 코드화:
B24: 2 | D24: pickTypeCd | K24: 피킹방식 | O24: varchar | Q24: 20 | W24: 총량피킹: 센터내 모든 지사를 총량으로 피킹 권역피킹: 지사별 총량으로 피킹 호차피킹: 차량단위 총량으로 피킹 점별피킹: 점포단위로 피킹
B25: 2 | D25: email | K25: 이메일 | L25: 이메일 | M25: 이메일 | N25: 이메일 | O25: varchar | Q25: 40(100)
B26: 2 | D26: tel | K26: 전화 | L26: 전화 | M26: 전화 | N26: 전화 | O26: varchar | Q26: 20
B27: 2 | D27: fax | K27: 팩스 | L27: 팩스 | M27: 팩스 | N27: 팩스 | O27: varchar | Q27: 20
B28: 2 | D28: postNo | K28: 우편_변호 | L28: 우편_변호 | M28: 우편_변호 | N28: 우편_변호 | O28: varchar | Q28: 10
B29: 2 | D29: addr | K29: 주소 | L29: 주소 | M29: 주소 | N29: 주소 | O29: varchar | Q29: 200
B30: 2 | D30: addrDtl | K30: 주소_상세 | L30: 주소 | M30: 주소 | N30: 주소 | O30: varchar | Q30: 200
B31: 2 | D31: note | K31: 비고 | L31: 비고 | M31: 비고 | N31: 비고 | O31: varchar | Q31: 1000
B32: 2 | D32: useYn | K32: 사용여부 | O32: char | Q32: 1 | U32: NN | W32: 코드화 : 'N' / 'Y' (기본'Y')
B34: Response
B35: LV | C35: 항목 | K35: 항목명 | O35: Type | Q35: SIZE | S35: KEY | U35: Null | W35: 설명
B36: 1 | C36: wmsResult | K36: WMS 처리 결과 | O36: varchar | Q36: 20 | U36: NN | W36: OK : 성공, NG : 실패
B37: 1 | C37: wmsMessage | K37: 메세지 | O37: varchar | Q37: 4000 | U37: NN | W37: 에러메세지
B38: 1 | C38: resList | K38: 요청리스트
B39: 2 | D39: ifContId | K39: IF_거래처_ID | O39: varchar | Q39: 50 | S39: O | U39: NN | W39: WMS와 외부 프로그램의 유니크 키
B40: 2 | D40: result | K40: 처리 여부 | O40: varchar | Q40: 1 | U40: NN | W40: OK : 성공, NG : 실패
B41: 2 | D41: message | K41: 처리 메시지 | O41: varchar | Q41: 100 | W41: 처리 실패시 실패 사유
B43: 비고

Sheet 기준_거래처_등록
A2: 인터페이스명 | B2: 거래처_등록
A3: 인터페이스 개요
A4: 인터페이스 상세 | B4: 1. ERP 연동 (ERP → WMS)
A5: Description | B5: WMS에서 ERP DB 접근하여 데이터 추출
A9: 인터페이스 유형 | I9: 적용방식 | J9: DB2DB
A10: 발생주기 | I10: 1일 발생 건수
A11: SOURCE | I11: TARGET
A12: 시스템 | B12: ERP | I12: 시스템 | J12: WMS
A13: INPUT | I13: INPUT
A14: Table Name | B14: Field | C14: Data Type | D14: PK | E14: Null | F14: Default Value | G14: Description | H14: 비고 | I14: Table Name | J14: Field | K14: Data Type | L14: PK | M14: Null | N14: Default Value | O14: Description | P14: 비고
A15: MA_Z_KCFNB_PARTNER_IF | B15: Seq | C15: BIGINT | D15: PK | E15: NN | G15: 생성순번(IDENTITY) | H15: 단순 숫자채번, MAX+1
A16: MA_Z_KCFNB_PARTNER_IF | B16: AUDType | C16: CHAR(1) | E16: NN | G16: 신규,수정/삭제 (A/D)
A17: MA_Z_KCFNB_PARTNER_IF | B17: CrtDateTime | C17: DATETIME | E17: NN | G17: 생성일시
A18: MA_Z_KCFNB_PARTNER_IF | B18: RecvYn | C18: CHAR(1) | F18: N | G18: 수신여부 (Y/N/E) | H18: WMS 미수신 = N WMS 수신 = Y 에러 = E
A19: MA_Z_KCFNB_PARTNER_IF | B19: RecvDateTime | C19: DATETIME | G19: 수신일시 | H19: WMS 데이터 수신 후 datetime UPDATE
A20: MA_Z_KCFNB_PARTNER_IF | B20: RecvYn_OMS | C20: CHAR(1) | F20: N | G20: 수신여부 (Y/N/E) | H20: WMS 미수신 = N WMS 수신 = Y 에러 = E
A21: MA_Z_KCFNB_PARTNER_IF | B21: RecvDateTime_OMS | C21: DATETIME | G21: 수신일시 | H21: OMS 데이터 수신 후 datetime UPDATE
A22: MA_Z_KCFNB_PARTNER_IF | B22: BizSeq | C22: INT | E22: NN | F22: 1 | G22: 사업장 SEQ | H22: 1: 교촌에프앤비 | I22: MDM_BIZ_CONT | J22: biz_seq | K22: INT
A23: MA_Z_KCFNB_PARTNER_IF | B23: sif_err_msg | C23: TEXT | G23: 에러메세지
A24: MA_Z_KCFNB_PARTNER_IF | B24: reg_id | C24: VARCHAR(20) | E24: NN | G24: 등록자ID | H24: 최초 등록자(사용자I/F 의 UserID) | I24: MDM_CONT | J24: reg_id | K24: VARCHAR(20)
A25: MA_Z_KCFNB_PARTNER_IF | B25: reg_dt | C25: DATETIME | E25: NN | G25: 등록일 | H25: 최초 등록일시 | I25: MDM_CONT | J25: reg_dt | K25: DATETIME
A26: MA_Z_KCFNB_PARTNER_IF | B26: mod_id | C26: VARCHAR(20) | G26: 수정자ID | H26: 데이터 최종수정자(사용자I/F 의 UserID) | I26: MDM_CONT | J26: mod_id | K26: VARCHAR(20)
A27: MA_Z_KCFNB_PARTNER_IF | B27: mod_dt | C27: DATETIME | G27: 수정일 | H27: 데이터 최종수정일시 | I27: MDM_CONT | J27: mod_dt | K27: DATETIME
A28: MA_Z_KCFNB_PARTNER_IF | B28: CD_COMPANY | C28: NVARCHAR(7) | D28: PK | E28: NN | G28: 회사코드 | J28: - | P28: WMS 관리 X
I29: MDM_CONT | J29: if_cont_id | K29: VARCHAR(50) | L29: PK | M29: NN | O29: IF_거래처_ID | P29: ERP(거래처코드:CD_PARTNER)로 대체
A30: MA_Z_KCFNB_PARTNER_IF | B30: CD_PARTNER | C30: NVARCHAR(20) | D30: PK | E30: NN | G30: 거래처코드 | I30: MDM_CONT | J30: cont_no | K30: VARCHAR(30) | M30: NN | O30: 거래처_번호
A31: MA_Z_KCFNB_PARTNER_IF | B31: LN_PARTNER | C31: NVARCHAR(50) | D31: PK | E31: NN | G31: 거래처명 | I31: MDM_CONT | J31: cont_nm | K31: VARCHAR(100) | M31: NN | O31: 거래처_명
A32: MA_Z_KCFNB_PARTNER_IF | B32: SN_PARTNER | C32: NVARCHAR(50) | G32: 거래처명(약칭) | I32: MDM_CONT | J32: cont_nm_short | K32: VARCHAR(100) | M32: NN | O32: 거래처_명_약칭
A33: MA_Z_KCFNB_PARTNER_IF | B33: TP_PARTNER | C33: NVARCHAR(3) | G33: 거래처타입 | H33: 공통코드 MA_B000002 내부, 외부, 직영점, 가맹점, 직영지사 등 | J33: - | P33: WMS 관리 X
A34: MA_Z_KCFNB_PARTNER_IF | B34: FG_PARTNER | C34: NVARCHAR(3) | G34: 거래처구분 | H34: 1(매입) / 2(매출) / 3(매입/매출) / 9(기타) --> 현재(2025-10-21) ERP 거래처 구분이 나눠지지 않았음 공통코드 MA_B000001 001 주요 002 금융 003 개인 004 신용 005 기타 | J34: - | P34: WMS 관리 X
A35: MA_Z_KCFNB_PARTNER_IF | B35: NM_CEO | C35: NVARCHAR(40) | G35: 대표자명 | I35: MDM_CONT | J35: ceo_nm | K35: VARCHAR(100) | O35: 대표자_명
A36: MA_Z_KCFNB_PARTNER_IF | B36: NO_COMPANY | C36: NVARCHAR(20) | G36: 사업자등록번호 | I36: MDM_CONT | J36: biz_no | K36: VARCHAR(20) | O36: 사업자_번호
A37: MA_Z_KCFNB_PARTNER_IF | B37: TP_JOB | C37: NVARCHAR(50) | G37: 업태 | H37: 명칭 | I37: MDM_CONT | J37: cont_type | K37: VARCHAR(100) | O37: 업태
A38: MA_Z_KCFNB_PARTNER_IF | B38: CLS_JOB | C38: NVARCHAR(50) | G38: 업종 | H38: 명칭 | I38: MDM_CONT | J38: cont_item | K38: VARCHAR(100) | O38: 종목
A39: MA_Z_KCFNB_PARTNER_IF | B39: CLS_PARTNER | C39: NVARCHAR(3) | G39: 거래처분류 | H39: 공통코드 MA_B000003 매입, 매출, 통합, 가맹점, 지사 등 001 매입 002 매출 003 통합 004 기타 005 가맹점 100 지사 | I39: MDM_CONT | J39: cont_div_cd | K39: VARCHAR(50) | M39: NN | O39: 거래처_구분코드
A40: MA_Z_KCFNB_PARTNER_IF | B40: NM_PTR | C40: NVARCHAR(20) | G40: 거래처담당자 | I40: MDM_CONT | J40: manager_nm | K40: VARCHAR(100) | O40: 담당자
A41: MA_Z_KCFNB_PARTNER_IF | B41: E_MAIL | C41: NVARCHAR(80) | G41: 담당자EMAIL | I41: MDM_CONT | J41: email | K41: VARCHAR(100) | O41: 이메일
A42: MA_Z_KCFNB_PARTNER_IF | B42: NO_TEL | C42: NVARCHAR(20) | G42: 전화번호 | J42: - | P42: WMS 관리 X
A43: MA_Z_KCFNB_PARTNER_IF | B43: NO_FAX | C43: NVARCHAR(20) | G43: 팩스번호 | J43: - | P43: WMS 관리 X
A44: MA_Z_KCFNB_PARTNER_IF | B44: NO_POST1 | C44: NVARCHAR(15) | G44: 본사우편번호 | I44: MDM_CONT | J44: post_no | K44: VARCHAR(10) | O44: 우편_변호
...

Sheet 기준_사번체크
A2: 인터페이스명 | B2: 사번체크
A3: 인터페이스 개요
A4: 인터페이스 상세 | B4: 1. ERP 연동 (HR → WMS)
A5: Description | B5: WMS에서 ERP DB 접근하여 데이터 추출 View로 제공
A9: 인터페이스 유형 | I9: 적용방식 | J9: DB2DB
A10: 발생주기 | I10: 1일 발생 건수
A11: SOURCE | I11: TARGET
A12: 시스템 | B12: ERP | I12: 시스템 | J12: WMS
A13: INPUT | I13: INPUT
A14: Table Name | B14: Field | C14: Data Type | D14: PK | E14: Null | F14: Default Value | G14: Description | H14: 비고 | I14: Table Name | J14: Field | K14: Data Type | L14: PK | M14: Null | N14: Default Value | O14: Description | P14: 비고
A15: V_MA_Z_KCFNB_EMP | B15: CD_COMPANY | C15: NVARCHAR(7) | D15: Y | E15: Y | F15: 1000 | G15: 회사코드
A16: V_MA_Z_KCFNB_EMP | B16: CD_BIZAREA | C16: NVARCHAR(7) | D16: Y | E16: Y | F16: 1000 | G16: 사업장코드
A17: V_MA_Z_KCFNB_EMP | B17: NO_EMP | C17: NVARCHAR(10) | D17: Y | E17: Y | G17: 사원번호
A18: V_MA_Z_KCFNB_EMP | B18: NM_KOR | C18: NVARCHAR(40) | G18: 사원명
A19: V_MA_Z_KCFNB_EMP | B19: CD_DEPT | C19: NVARCHAR(12) | E19: Y | G19: 부서코드
A20: V_MA_Z_KCFNB_EMP | B20: NM_DEPT | C20: NVARCHAR(50) | G20: 부서명
A21: V_MA_Z_KCFNB_EMP | B21: DT_RETIRE | C21: NVARCHAR(200) | G21: 퇴직일자 | H21: null or 공백이면 '재직중' / 아니면 '퇴직자'
A22: V_MA_Z_KCFNB_EMP | B22: ID_INSERT | C22: NVARCHAR(15) | G22: 입력자 | J22: cont_close_ymd
A23: V_MA_Z_KCFNB_EMP | B23: DTS_INSERT | C23: NVARCHAR(14) | G23: 입력일시
A24: V_MA_Z_KCFNB_EMP | B24: ID_UPDATE | C24: NVARCHAR(15) | G24: 수정자
A25: V_MA_Z_KCFNB_EMP | B25: DTS_UPDATE | C25: NVARCHAR(14) | G25: 수정일시
A28: 기타

Sheet 기준_사번체크_bak
A1: 목록
B2: IF명 | E2: =ERP_인터페이스목록!C6 -> 사번체크 | O2: ifId | R2: =ERP_인터페이스목록!G6 -> W2E_EMP_CHK
B3: URI | E3: =ERP_인터페이스목록!J6 -> 0
B4: HTTP Method | E4: =ERP_인터페이스목록!L6 -> DB to DB | O4: Data Type | R4: JSON
B5: SOURCE | E5: =ERP_인터페이스목록!D6 -> WMS | O5: TARGET | R5: E6
B7: Request
B8: LV | C8: 항목 | K8: 항목명 | O8: Type | Q8: SIZE | S8: KEY | U8: Null | W8: 설명
B9: 1 | C9: bizSeq | K9: 사업장SEQ | O9: number | Q9: 10 | U9: NN | W9: WMS 회원 가입시 발행된 BIZ_SEQ
B10: 1 | C10: userId | K10: 등록자ID | O10: varchar | Q10: 20 | U10: NN | W10: 타시스템ID/WMS사용자 ID
B11: 1 | C11: userNm | K11: 등록자명 | O11: varchar | Q11: 100 | U11: NN | W11: 타시스템사용자명/WMS사용자명
B12: 1 | C12: reqList | K12: 요청리스트
B13: 2 | D13: userNm | K13: 사용자명 | O13: varchar | Q13: 20 | S13: O | U13: NN
B14: 2 | D14: empNo | K14: 사번 | O14: varchar | Q14: 20 | S14: O | U14: NN
B16: Response
B17: LV | C17: 항목 | K17: 항목명 | O17: Type | Q17: SIZE | S17: KEY | U17: Null | W17: 설명
B18: 1 | C18: wmsResult | K18: WMS 처리 결과 | O18: varchar | Q18: 20 | U18: NN | W18: OK : 성공, NG : 실패
B19: 1 | C19: wmsMessage | K19: 메세지 | O19: varchar | Q19: 4000 | U19: NN | W19: 에러메세지
B20: 1 | C20: resList | K20: 요청리스트
B21: 2 | D21: userNm | K21: 사용자명 | O21: varchar | Q21: 20 | S21: O | U21: NN
B22: 2 | D22: empNo | K22: 사번 | O22: varchar | Q22: 20 | S22: O | U22: NN
B23: 2 | D23: result | K23: 처리 여부 | O23: varchar | Q23: 1 | U23: NN | W23: OK : 성공, NG : 실패
B24: 2 | D24: message | K24: 처리 메시지 | O24: varchar | Q24: 100 | W24: 처리 실패시 실패 사유
B26: 비고
B27: 퇴사자의 경우 ERP Response 실패(E)로 전달. 처리 메시지에 '퇴직자 입니다.' 등으로 리턴.

Sheet 입고_입고예정_등록
A2: 인터페이스명 | B2: 입고예정_등록
A3: 인터페이스 개요
A4: 인터페이스 상세 | B4: 1. ERP 연동 (ERP → WMS)
A5: Description | B5: WMS에서 ERP DB 접근하여 데이터 추출 구매입고, 외주입고 시 IF
A9: 인터페이스 유형 | I9: 적용방식 | J9: DB2DB
A10: 발생주기 | I10: 1일 발생 건수
A11: SOURCE | I11: TARGET
A12: 시스템 | B12: ERP | I12: 시스템 | J12: WMS
A13: INPUT | I13: INPUT
A14: Table Name | B14: Field | C14: Data Type | D14: PK | E14: Null | F14: Default Value | G14: Description | H14: 비고 | I14: Table Name | J14: Field | K14: Data Type | L14: PK | M14: Null | N14: Default Value | O14: Description | P14: 비고
A15: PU_Z_KCFNB_RCV_IF | B15: Seq | C15: BIGINT | D15: PK | E15: NN | G15: 생성순번(IDENTITY) | H15: 단순 숫자채번, MAX+1
A16: PU_Z_KCFNB_RCV_IF | B16: AUDType | C16: CHAR(1) | E16: NN | G16: 신규,수정/삭제 (A/D) | H16: A : 발주/의뢰 데이터 최초 INSERT 및 상태값 변경 시 D : 발주/의뢰 삭제 또는 상태값 종결 시(PU_POL.FG_POST = 'C' AND PU_POL.QT_RCV = 0)
A17: PU_Z_KCFNB_RCV_IF | B17: CrtDateTime | C17: DATETIME | E17: NN | G17: 생성일시 | H17: INSERT 시점의 SYSDATE
A18: PU_Z_KCFNB_RCV_IF | B18: RecvYn | C18: CHAR(1) | F18: N | G18: 수신여부 (Y/N) | H18: RecvYn = 'N' 1. ERP INSERT 시, Default 값 2. ERP 발주관리 메뉴에서 '종결처리' 가능 종결 시, AUDType ='D' 로 신규 SEQ INSERT RecvYn = 'Y' 1. WMS 수신 시, UPDATE 예정 2. ERP 발주관리 메뉴에서 '종결처리' 가능 종결 시, AUDType ='D' 로 신규 SEQ INSERT RecvYn = 'P' 1. WMS 내 입고중일 시, UPDATE 예정 2. ERP 발주관리 메뉴에서 종결처리, 확정취소 불가 RecvYn = 'E' 1. WMS에서 데이터 취합 중 에러발생 시 UPDATE 예정
A19: PU_Z_KCFNB_RCV_IF | B19: RecvDateTime | C19: DATETIME | G19: 수신일시 | H19: WMS 데이터 수신 후 getdate()로 업데이트 처리
A20: PU_Z_KCFNB_RCV_IF | B20: BizSeq | C20: INT | E20: NN | F20: 1 | G20: 사업장 SEQ | H20: 1: 교촌에프앤비 | I20: WMS_INWH | J20: biz_seq | K20: INT
A21: PU_Z_KCFNB_RCV_IF | B21: sif_err_msg | C21: TEXT | G21: 에러메세지
A22: PU_Z_KCFNB_RCV_IF | B22: reg_id | C22: VARCHAR(20) | E22: NN | G22: 등록자ID | H22: 최초 등록자(사용자I/F 의 UserID) | I22: WMS_INWH / WMS_INWH_PROD | J22: reg_id | K22: VARCHAR(20)
A23: PU_Z_KCFNB_RCV_IF | B23: reg_dt | C23: DATETIME | E23: NN | G23: 등록일 | H23: 최초 등록일시 | I23: WMS_INWH / WMS_INWH_PROD | J23: reg_dt | K23: DATETIME
A24: PU_Z_KCFNB_RCV_IF | B24: mod_id | C24: VARCHAR(20) | G24: 수정자ID | H24: 데이터 최종수정자(사용자I/F 의 UserID) | I24: WMS_INWH / WMS_INWH_PROD | J24: mod_id | K24: VARCHAR(20)
A25: PU_Z_KCFNB_RCV_IF | B25: mod_dt | C25: DATETIME | G25: 수정일 | H25: 데이터 최종수정일시 | I25: WMS_INWH / WMS_INWH_PROD | J25: mod_dt | K25: DATETIME
I26: WMS_INWH | J26: if_Key | K26: VARCHAR(50) | L26: PK | M26: NN | O26: IF 키 | P26: ERP 입고의뢰번호
I27: WMS_INWH_PROD | J27: if_idx | K27: VARCHAR(20) | O27: I/F 서브키 | P27: ERP 입고항번 타입변경 필요(int -> varchar)
I28: WMS_INWH | J28: inwh_type_cd | K28: VARCHAR(50) | L28: PK | M28: NN | O28: 요청유형코드 | P28: IW01:구매입고(자사센터 입고) IW03:외주입고(외주센터입고) ERP입고창고(CD_SL)로 요청유형(inwh_type_cd) 책정하여 삽입
A29: PU_Z_KCFNB_RCV_IF | B29: CD_COMPANY | C29: NVARCHAR(7) | E29: NN | F29: 1000 | G29: 회사코드 | H29: 입고 마감 시 ERP 전달용 | I29: WMS_INWH | J29: erp_company_cd | K29: VARCHAR(7) | M29: NN | O29: ERP 회사코드 | P29: 신규컬럼 추가
A30: PU_Z_KCFNB_RCV_IF | B30: CD_PLANT | C30: NVARCHAR(7) | E30: NN | F30: 1000 | G30: 공장코드 | H30: 입고 마감 시 ERP 전달용 | I30: WMS_INWH | J30: erp_plant_cd | K30: VARCHAR(7) | M30: NN | O30: ERP 공장코드 | P30: 신규컬럼 추가
A31: PU_Z_KCFNB_RCV_IF | B31: NO_RCV | C31: NVARCHAR(20) | G31: 입고의뢰번호 | H31: 입고 마감 시 ERP 전달용 | I31: WMS_INWH | J31: req_no | K31: VARCHAR(30) | O31: 문서_번호(타시스템)
A32: PU_Z_KCFNB_RCV_IF | B32: NO_LINE | C32: NUMERIC(5,0) | G32: 입고의뢰항번 | H32: 입고 마감 시 ERP 전달용 | I32: WMS_INWH_PROD | J32: erp_line_no | K32: INT | O32: ERP 입고의뢰항번 | P32: D1에 신규컬럼 추가 필요
A33: PU_Z_KCFNB_RCV_IF | B33: NO_PO | C33: NVARCHAR(20) | G33: 발주번호 | H33: 입고 마감 시 ERP 전달용 | I33: WMS_INWH_PROD | J33: erp_po_no | K33: VARCHAR(20) | O33: ERP 발주번호 | P33: D1에 신규컬럼 추가 필요
A34: PU_Z_KCFNB_RCV_IF | B34: NO_POLINE | C34: NUMERIC(5,0) | G34: 발주항번 | H34: 입고 마감 시 ERP 전달용 | I34: WMS_INWH_PROD | J34: erp_poline_no | K34: INT | O34: ERP 발주항번 | P34: D1에 신규컬럼 추가 필요
I35: WMS_INWH | J35: center_seq | K35: INT | M35: NN | O35: 센터SEQ | P35: ERP입고창고 기준으로 센터정보 셋팅 "센터정보" 시트 참조
A36: PU_Z_KCFNB_RCV_IF | B36: CD_ITEM | C36: NVARCHAR(20) | E36: NN | G36: 품목코드 | I36: WMS_INWH_PROD | J36: prod_seq | K36: VARCHAR(50) | M36: NN | O36: 품목번호 | P36: 품목ID => 품목SEQ 변환 후 저장
A37: PU_Z_KCFNB_RCV_IF | B37: DT_REQ | C37: NVARCHAR(8) | G37: 입고의뢰일 | P37: WMS 관리 X
A38: PU_Z_KCFNB_RCV_IF | B38: DT_LIMIT | C38: NVARCHAR(8) | E38: NN | G38: 납기일 | I38: WMS_INWH | J38: req_ymd | K38: VARCHAR(8) | M38: NN | O38: 예정연월일
A39: PU_Z_KCFNB_RCV_IF | B39: QT_REQ_MM | C39: NUMERIC(17,4) | E39: NN | G39: 입고의뢰수량 | I39: WMS_INWH_PROD | J39: req_qty | K39: INT | M39: NN | O39: 요청수량
A40: PU_Z_KCFNB_RCV_IF | B40: YN_RETURN | C40: NCHAR(1) | E40: NN | F40: N | G40: 반품여부 | H40: 입고 마감 시 ERP 전달 해당 테이블에서는 Default 값만 INSERT 'Y'의 케이스는 예외출고요청에 존재 | I40: WMS_INWH_PROD | J40: erp_return_yn | K40: CHAR(1) | O40: ERP 반품여부 | P40: 신규컬럼 추가
A41: PU_Z_KCFNB_RCV_IF | B41: NO_EMP | C41: NVARCHAR(10) | G41: 입고의뢰담당자_사번 | P41: WMS 관리 X
A42: PU_Z_KCFNB_RCV_IF | B42: NM_KOR | C42: NVARCHAR(40) | G42: 입고의뢰담당자_명 | I42: WMS_INWH | J42: req_user_nm | K42: VARCHAR(100) | O42: 요청_사용자_명(입고)
A43: PU_Z_KCFNB_RCV_IF | B43: CD_TPPO | C43: NVARCHAR(7) | E43: NN | G43: 발주유형 | H43: 입고 마감 시 ERP 전달용 | I43: WMS_INWH | J43: erp_tppo_cd | K43: VARCHAR(7) | M43: NN | O43: ERP 발주유형 | P43: 신규컬럼 추가 필요
A44: PU_Z_KCFNB_RCV_IF | B44: CD_QTIOTP | C44: NCHAR(3) | E44: NN | G44: 수불유형 | H44: 입고 마감 시 ERP 전달용 | I44: WMS_INWH | J44: erp_qtiotp_cd | K44: VARCHAR(3) | M44: NN | O44: ERP 수불유형 | P44: 신규컬럼 추가 필요
...

Sheet 입고_예외입고_등록
A2: 인터페이스명 | B2: 예외입고_등록
A3: 인터페이스 개요
A4: 인터페이스 상세 | B4: 1. ERP 연동 (ERP → WMS)
A5: Description | B5: WMS에서 ERP DB 접근하여 데이터 추출 예외입고_등록 : 원자재외주센터 -> 자사센터 재고이동 처리
A9: 인터페이스 유형 | I9: 적용방식 | J9: DB2DB
A10: 발생주기 | I10: 1일 발생 건수
A11: SOURCE | I11: TARGET
A12: 시스템 | B12: ERP | I12: 시스템 | J12: WMS
A13: INPUT | I13: INPUT
A14: Table Name | B14: Field | C14: Data Type | D14: PK | E14: Null | F14: Default Value | G14: Description | H14: 비고 | I14: Table Name | J14: Field | K14: Data Type | L14: PK | M14: Null | N14: Default Value | O14: Description | P14: 비고
A15: MM_Z_KCFNB_MSL_IF | B15: Seq | C15: BIGINT | D15: PK | E15: NN | G15: 생성순번(IDENTITY) | H15: 단순 숫자채번, MAX+1
A16: MM_Z_KCFNB_MSL_IF | B16: AUDType | C16: CHAR(1) | E16: NN | G16: 신규,수정/삭제 (A/D) | H16: A : 발주/의뢰 데이터 최초 INSERT 및 상태값 변경 시 D : 발주/의뢰 삭제 또는 상태값 종결 시(PU_POL.FG_POST = 'C' AND PU_POL.QT_RCV = 0)
A17: MM_Z_KCFNB_MSL_IF | B17: CrtDateTime | C17: DATETIME | E17: NN | G17: 생성일시 | H17: INSERT 시점의 SYSDATE
A18: MM_Z_KCFNB_MSL_IF | B18: RecvYn | C18: CHAR(1) | F18: N | G18: 수신여부 (Y/N) | H18: RecvYn = 'N' 1. ERP INSERT 시, Default 값 2. ERP 발주관리 메뉴에서 '종결처리' 가능 종결 시, AUDType ='D' 로 신규 SEQ INSERT RecvYn = 'Y' 1. WMS 수신 시, UPDATE 예정 2. ERP 발주관리 메뉴에서 '종결처리' 가능 종결 시, AUDType ='D' 로 신규 SEQ INSERT RecvYn = 'P' 1. WMS 내 입고중일 시, UPDATE 예정 2. ERP 발주관리 메뉴에서 종결처리, 확정취소 불가 RecvYn = 'E' 1. WMS에서 데이터 취합 중 에러발생 시 UPDATE 예정
A19: MM_Z_KCFNB_MSL_IF | B19: RecvDateTime | C19: DATETIME | G19: 수신일시 | H19: WMS 데이터 수신 후 getdate()로 업데이트 처리
A20: MM_Z_KCFNB_MSL_IF | B20: BizSeq | C20: INT | E20: NN | F20: 1 | G20: 사업장 SEQ | H20: 1: 교촌에프앤비 | I20: WMS_INWH | J20: biz_seq | K20: INT
A21: MM_Z_KCFNB_MSL_IF | B21: sif_err_msg | C21: TEXT | G21: 에러메세지
A22: MM_Z_KCFNB_MSL_IF | B22: reg_id | C22: VARCHAR(20) | E22: NN | G22: 등록자ID | H22: 최초 등록자(사용자I/F 의 UserID) | I22: WMS_INWH / WMS_INWH_PROD | J22: reg_id | K22: VARCHAR(20)
A23: MM_Z_KCFNB_MSL_IF | B23: reg_dt | C23: DATETIME | E23: NN | G23: 등록일 | H23: 최초 등록일시 | I23: WMS_INWH / WMS_INWH_PROD | J23: reg_dt | K23: DATETIME
A24: MM_Z_KCFNB_MSL_IF | B24: mod_id | C24: VARCHAR(20) | G24: 수정자ID | H24: 데이터 최종수정자(사용자I/F 의 UserID) | I24: WMS_INWH / WMS_INWH_PROD | J24: mod_id | K24: VARCHAR(20)
A25: MM_Z_KCFNB_MSL_IF | B25: mod_dt | C25: DATETIME | G25: 수정일 | H25: 데이터 최종수정일시 | I25: WMS_INWH / WMS_INWH_PROD | J25: mod_dt | K25: DATETIME
I26: WMS_INWH | J26: if_Key | K26: VARCHAR(50) | L26: PK | M26: NN | O26: IF 키 | P26: ERP 요청번호
I27: WMS_INWH_PROD | J27: if_idx | K27: VARCHAR(20) | O27: I/F 서브키 | P27: ERP 요청항번 타입변경 필요(int -> varchar)
I28: WMS_INWH | J28: inwh_type_cd | K28: VARCHAR(50) | L28: PK | M28: NN | O28: 요청유형코드 | P28: IW91:예외입고
A29: MM_Z_KCFNB_MSL_IF | B29: CD_COMPANY | C29: NVARCHAR(7) | D29: PK | E29: NN | F29: 1000 | G29: 회사코드 | H29: 입고 마감 시 ERP 전달용 | I29: WMS_INWH | J29: erp_company_cd | K29: VARCHAR(7) | M29: NN | O29: ERP 회사코드 | P29: 신규컬럼 추가
A30: MM_Z_KCFNB_MSL_IF | B30: CD_PLANT | C30: NVARCHAR(7) | D30: PK | E30: NN | F30: 1000 | G30: 공장코드 | H30: 입고 마감 시 ERP 전달용 | I30: WMS_INWH | J30: erp_plant_cd | K30: VARCHAR(7) | M30: NN | O30: ERP 공장코드 | P30: 신규컬럼 추가
A31: MM_Z_KCFNB_MSL_IF | B31: NO_GIREQ | C31: NVARCHAR(20) | D31: PK | E31: NN | G31: 요청번호 | H31: 입고 마감 시 ERP 전달용 | I31: WMS_INWH | J31: req_no | K31: VARCHAR(30) | O31: 문서_번호(타시스템)
A32: MM_Z_KCFNB_MSL_IF | B32: NO_LINE | C32: NUMERIC(5) | D32: PK | E32: NN | G32: 요청항번 | H32: 입고 마감 시 ERP 전달용 | I32: WMS_INWH_PROD | J32: erp_line_no | K32: INT | O32: ERP 입고의뢰항번 | P32: D1에 신규컬럼 추가 필요
A33: MM_Z_KCFNB_MSL_IF | B33: NO_PO | C33: NVARCHAR(20) | F33: NULL | G33: 발주번호 | H33: 입고 마감 시 ERP 전달용 | I33: WMS_INWH_PROD | J33: erp_po_no | K33: VARCHAR(20) | O33: ERP 발주번호 | P33: D1에 신규컬럼 추가 필요
A34: MM_Z_KCFNB_MSL_IF | B34: NO_POLINE | C34: NUMERIC(5,0) | F34: 0 | G34: 발주항번 | H34: 입고 마감 시 ERP 전달용 | I34: WMS_INWH_PROD | J34: erp_poline_no | K34: INT | O34: ERP 발주항번 | P34: D1에 신규컬럼 추가 필요
I35: WMS_INWH | J35: center_seq | K35: INT | M35: NN | O35: 센터SEQ | P35: 창고코드(TO) 기준으로 센터정보 셋팅 "센터정보" 시트 참조
A36: MM_Z_KCFNB_MSL_IF | B36: CD_SL | C36: NVARCHAR(7) | G36: 창고코드(FROM) | H36: 입고 마감 시 ERP 전달용 | I36: WMS_INWH | J36: erp_sl_cd | K36: VARCHAR(7) | O36: ERP 출고창고 (원자재외주센터) | P36: 신규컬럼 추가 필요
A37: MM_Z_KCFNB_MSL_IF | B37: CD_GRSL | C37: NVARCHAR(7) | G37: 창고코드(TO) | H37: ERP 입고창고 입고창고, 누락 시 E로 리턴, ERP 창고입력 후 재저장 | I37: WMS_INWH | J37: erp_grsl_cd | K37: VARCHAR(7) | M37: NN | O37: ERP 입고창고 (자사센터) | P37: 신규컬럼 추가 필요
A38: MM_Z_KCFNB_MSL_IF | B38: FG_GIREQ | C38: NCHAR(3) | G38: 수불유형 | H38: 입고 마감 시 ERP 전달용 | I38: WMS_INWH | J38: erp_qtiotp_cd | K38: VARCHAR(3) | M38: NN | O38: ERP 수불유형 | P38: 신규컬럼 추가 필요
A39: MM_Z_KCFNB_MSL_IF | B39: FG_IO | C39: NCHAR(3) | G39: 수불구분 | H39: 입고 마감 시 ERP 전달용 | I39: WMS_INWH | J39: erp_io_fg | K39: VARCHAR(3) | O39: ERP 수불구분 | P39: 신규컬럼 추가 필요
A40: MM_Z_KCFNB_MSL_IF | B40: DT_GIREQ | C40: NCHAR(8) | G40: 요청등록일 | P40: WMS 관리 X
A41: MM_Z_KCFNB_MSL_IF | B41: DT_DELIVERY | C41: NCHAR(8) | G41: 납품예정일 | I41: WMS_INWH | J41: req_ymd | K41: VARCHAR(8) | M41: NN | O41: 예정연월일
A42: MM_Z_KCFNB_MSL_IF | B42: NO_EMP | C42: NVARCHAR(10) | G42: 요청자_사번 | P42: WMS 관리 X
A43: MM_Z_KCFNB_MSL_IF | B43: NM_KOR | C43: NVARCHAR(40) | G43: 요청자명 | I43: WMS_INWH | J43: req_user_nm | K43: VARCHAR(100) | O43: 요청_사용자_명(입고)
A44: MM_Z_KCFNB_MSL_IF | B44: CD_DEPT | C44: NVARCHAR(10) | G44: 요청자부서 | P44: WMS 관리 X
...

Sheet 입고_마감
A2: 인터페이스명 | B2: 입고마감
A3: 인터페이스 개요
A4: 인터페이스 상세 | B4: 1. WMS 연동 (WMS → ERP)
A5: Description | B5: IF테이블은 ERP DB 스키마에 생성 및 데이터 관리 WMS에서 ERP DB에 직접 접근해 데이터 입력함 입고예정_등록(구매입고,외주입고), 예외입고(예외입고), 외주직출(센터입고, 외주센터입고) 마감 시 IF
A9: 인터페이스 유형 | I9: 적용방식 | J9: DB2DB
A10: 발생주기 | I10: 1일 발생 건수
A11: SOURCE | I11: TARGET
A12: 시스템 | B12: WMS | I12: 시스템 | J12: ERP
A13: INPUT | I13: INPUT
A14: Table Name | B14: Field | C14: Data Type | D14: PK | E14: Null | F14: Default Value | G14: Description | H14: 비고 | I14: Table Name | J14: Field | K14: Data Type | L14: PK | M14: Null | N14: Default Value | O14: Description | P14: 비고
G15: 생성순번(IDENTITY) | H15: 최초 1, 데이터 INSERT 될때마다, MAX+1 | I15: MM_Z_KCFNB_QTIO_IF | J15: seq | K15: BIGINT | L15: PK | M15: NN | O15: 생성순번(IDENTITY)
G16: 신규,수정/삭제 (A/D) | H16: A : 생성 데이터 insert 시 D : 데이터 삭제 시 | I16: MM_Z_KCFNB_QTIO_IF | J16: AUDType | K16: CHAR(1) | M16: NN | O16: 신규,수정/삭제 (A/D)
A17: WMS_INWH | B17: erp_company_cd | C17: VARCHAR(7) | E17: NN | G17: ERP 회사코드 | H17: 입고예정_등록 시 전달받은 값 | I17: MM_Z_KCFNB_QTIO_IF | J17: CD_COMPANY | K17: NVARCHAR(7) | L17: PK | M17: NN | N17: 1000 | O17: 회사코드
H18: 디폴트 1000로 셋팅 | I18: MM_Z_KCFNB_QTIO_IF | J18: CD_BIZAREA | K18: NVARCHAR(7) | L18: PK | M18: NN | N18: 1000 | O18: 사업장코드 | P18: 없으면 디폴트 1000
A19: WMS_INWH | B19: erp_plant_cd | C19: VARCHAR(7) | E19: NN | G19: ERP 공장코드 | H19: 입고예정_등록 시 전달받은 값 | I19: MM_Z_KCFNB_QTIO_IF | J19: CD_PLANT | K19: NVARCHAR(7) | L19: PK | M19: NN | N19: 1000 | O19: 공장코드
A20: WMS_INWH | B20: inwh_no | C20: varchar(30) | E20: NN | G20: 입고_번호 | H20: WMS 입고 업무번호 | I20: MM_Z_KCFNB_QTIO_IF | J20: NO_POP | K20: NVARCHAR(30) | L20: PK | M20: NN | O20: 연동번호 | P20: WMS 문서번호(입고번호, 예외출고번호, 반품번호)
H21: insert 시 품목순번 채번하여 입력 | I21: MM_Z_KCFNB_QTIO_IF | J21: NO_POP_LINE | K21: NUMERIC(5, 0) | L21: PK | M21: NN | O21: 연동항번 | P21: 품목 항목
A22: WMS_INWH | B22: erp_sl_cd | C22: VARCHAR(7) | E22: NN | G22: ERP 입고창고 | H22: 구매입고/외주입고/예외입고 : - 수신 시 전달받은 값(erp_sl_cd) 센터입고/외주센터입고 : - 출하D2의 처리창고의 ERP IF 창고코드 | I22: MM_Z_KCFNB_QTIO_IF | J22: CD_SL | K22: NVARCHAR(7) | M22: NN | O22: 창고코드 | P22: WMS처리창고(from) 출고창고, 입고창고, 반입창고 등등
H23: 디폴트 null로 셋팅 | I23: MM_Z_KCFNB_QTIO_IF | J23: NO_IO | K23: NVARCHAR(20) | N23: NULL | O23: 수불번호 | P23: null로 셋팅
H24: 디폴트 0으로 셋팅 | I24: MM_Z_KCFNB_QTIO_IF | J24: NO_IOLINE | K24: NUMERIC(5, 0) | N24: 0 | O24: 수불항번 | P24: 디폴트 0
A25: WMS_INWH_TRAN | B25: proc_ymd | C25: varchar(8) | G25: 처리_연월일(입고) | H25: 품목별 처리일자 그룹핑 후 MAX값으로 전달 | I25: MM_Z_KCFNB_QTIO_IF | J25: DT_IO | K25: NCHAR(8) | M25: NN | O25: 수불일자 | P25: WMS처리일자
A26: WMS_INWH | B26: req_no | C26: VARCHAR(30) | G26: 문서_번호(타시스템) | I26: MM_Z_KCFNB_QTIO_IF | J26: NO_ISURCV | K26: NVARCHAR(20) | N26: NULL | O26: 의뢰번호 | P26: 요청데이터 존재할 경우 출고요청.NO_GIREQ WMS 자체처리의 경우 NULL
A27: WMS_INWH_PROD | B27: erp_line_no | C27: INT | G27: ERP 입고의뢰항번 | H27: 입고예정_등록 시 전달받은 값 | I27: MM_Z_KCFNB_QTIO_IF | J27: NO_ISURCVLINE | K27: NUMERIC(5, 0) | N27: 0 | O27: 의뢰항번 | P27: 요청데이터 존재할 경우 출고요청.NO_LINE WMS 자체처리의 경우 NULL
A28: WMS_INWH_PROD | B28: erp_po_no | C28: VARCHAR(20) | G28: ERP 발주번호 | H28: 입고예정_등록 시 전달받은 값 | I28: MM_Z_KCFNB_QTIO_IF | J28: NO_PSO_MGMT | K28: NVARCHAR(20) | N28: NULL | O28: 오더번호 | P28: 구매반품의 경우 출고요청.NO_PO WMS 자체처리의 경우 NULL
A29: WMS_INWH_PROD | B29: erp_poline_no | C29: INT | G29: ERP 발주항번 | H29: 입고예정_등록 시 전달받은 값 | I29: MM_Z_KCFNB_QTIO_IF | J29: NO_PSOLINE_MGMT | K29: NUMERIC(5, 0) | N29: 0 | O29: 오더항번 | P29: 구매반품의 경우 출고요청.NO_POLINE WMS 자체처리의 경우 NULL
H30: 1: 구매입고/외주입고 2:예외입고/센터입고/외주센터입고 | I30: MM_Z_KCFNB_QTIO_IF | J30: FG_PS | K30: NCHAR(1) | M30: NN | O30: 입/출고구분 | P30: 입고 : 1, 출고 : 2 / 재고이동='2'
H31: Y: 구매입고/외주입고 N:예외입고/센터입고/외주센터입고 | I31: MM_Z_KCFNB_QTIO_IF | J31: YN_PURSALE | K31: NCHAR(1) | O31: 거래여부 | P31: 구매반품의 경우 Y, 그 외 Default 값 구매관련 Y, 나머지 N
A32: WMS_INWH | B32: erp_tppo_cd | C32: VARCHAR(7) | E32: NN | G32: ERP 발주유형 | H32: 입고예정_등록 시 전달받은 값 | I32: MM_Z_KCFNB_QTIO_IF | J32: CD_TPPO | K32: NVARCHAR(7) | O32: 발주유형
A33: WMS_INWH | B33: erp_qtiotp_cd | C33: VARCHAR(3) | E33: NN | G33: ERP 수불유형 | H33: 입고예정_등록 시 전달받은 값 | I33: MM_Z_KCFNB_QTIO_IF | J33: CD_QTIOTP | K33: NCHAR(3) | O33: 수불유형 | P33: 구매+B32:P32입고(100), 구매반품(130), 재고이동(500), 계정대체출고
A34: WMS_INWH | B34: erp_io_fg | C34: VARCHAR(3) | G34: ERP 수불구분 | H34: 입고예정_등록 시 전달받은 값 | I34: MM_Z_KCFNB_QTIO_IF | J34: FG_IO | K34: NCHAR(3) | O34: 수불구분 | P34: 012' 계정대체출고, '022'창고이동, '030' 구매반품 고정
H35: 디폴트 null로 셋팅 | I35: MM_Z_KCFNB_QTIO_IF | J35: FG_TPIO | K35: NVARCHAR(3) | N35: NULL | O35: 대체유형 | P35: 출고요청 시, FG_GIREQ = '401' 인 경우 FG_GI값
A36: WMS_INWH_PROD | B36: prod_seq | C36: int4 | E36: NN | G36: 품목_SEQ | H36: IF_PROD_ID로 컨버팅 후 입력 | I36: MM_Z_KCFNB_QTIO_IF | J36: CD_ITEM | K36: NVARCHAR(20) | O36: 품목코드
A37: WMS_INWH_PROD | B37: ex_qty | C37: decimal(10,2) | E37: NN | G37: 기처리_수량(입고) | I37: MM_Z_KCFNB_QTIO_IF | J37: QT_IO | K37: NUMERIC(17, 4) | M37: NN | O37: 수불수량 | P37: 실적수량 정수만….(재고단위 수량 EA수량으로)
A38: WMS_INWH | B38: cont_seq | C38: VARCHAR(50) | G38: IF_거래처_ID | H38: 거래처SEQ => 거래처ID 변환 후 저장 | I38: MM_Z_KCFNB_QTIO_IF | J38: CD_PARTNER | K38: NVARCHAR(20) | N38: NULL | O38: 거래처 | P38: 있으면 주고 없으면 NULL
A39: WMS_INWH_TRAN | B39: proc_user_id | C39: varchar(20) | G39: 처리_자_ID(입고) | H39: 품목별 처리자 그룹핑 후 마지막 처리자 전달 처리자ID => 사번으로 변환 후 입력 | I39: MM_Z_KCFNB_QTIO_IF | J39: NO_EMP | K39: NVARCHAR(10) | O39: 담당자 | P39: WMS실적처리담당자 사번으로 넘겨
A40: WMS_INWH_PROD | B40: erp_purgrp_cd | C40: VARCHAR(7) | G40: ERP 구매그룹 | H40: 입고예정_등록 시 전달받은 값 | I40: MM_Z_KCFNB_QTIO_IF | J40: CD_GROUP | K40: NVARCHAR(7) | N40: NULL | O40: 그룹코드 | P40: 구매입고/반품일 경우 INSERT(CD_PURGRP), 그 외 NULL
A41: WMS_INWH | B41: erp_grsl_cd | C41: VARCHAR(7) | G41: ERP 창고코드(TO) | H41: 예외입고 : - 수신 시 전달받은 값(erp_grsl_cd) 센터입고/외주센터입고 : - 입고D2의 처리창고의 ERP IF 창고코드 | I41: MM_Z_KCFNB_QTIO_IF | J41: CD_SL_REF | K41: NVARCHAR(7) | N41: NULL | O41: 창고코드(연계) | P41: 센터간 재고이동일 경우 입고창고 insert, 그 외 null
A42: WMS_INWH | B42: note | C42: varchar(1000) | G42: 비고 | I42: MM_Z_KCFNB_QTIO_IF | J42: DC_RMK | K42: NVARCHAR(100) | N42: NULL | O42: 비고 | P42: WMS실적비고정보
A43: WMS_INWH_PROD | B43: erp_exch_cd | C43: VARCHAR(3) | G43: ERP 환종 | H43: 입고예정_등록 시 전달받은 값 | I43: MM_Z_KCFNB_QTIO_IF | J43: CD_EXCH | K43: NVARCHAR(3) | N43: 000 | O43: 환종 | P43: 요청데이터 존재 시 출고요청의 동일한 CD_EXCH, 그 외 Default
A44: WMS_INWH_PROD | B44: erp_exch_rt | C44: INT | G44: ERP 환율 | H44: 입고예정_등록 시 전달받은 값 | I44: MM_Z_KCFNB_QTIO_IF | J44: RT_EXCH | K44: NUMERIC(11,4) | N44: 1.0000 | O44: 환율 | P44: 요청데이터 존재 시 출고요청의 동일한 RT_EXCH, 그 외 Default
...

Sheet 반품_반품예정 등록
A1: 목록
B2: IF명 | E2: =ERP_인터페이스목록!C10 -> 반품예정 등록 | O2: ifId | R2: =ERP_인터페이스목록!G10 -> O2W_RT_REG
B3: URI | E3: =ERP_인터페이스목록!J10 -> /{bizSeq}/sif/rtrq01/regs
B4: HTTP Method | E4: =ERP_인터페이스목록!L10 -> POST | O4: Data Type | R4: JSON
B5: SOURCE | E5: =ERP_인터페이스목록!D10 -> OMS | O5: TARGET | R5: =ERP_인터페이스목록!E10 -> WMS
B7: Request
B8: LV | C8: 항목 | K8: 항목명 | O8: Type | Q8: SIZE | S8: KEY | U8: Null | W8: 설명
B9: 1 | C9: bizSeq | K9: 사업장SEQ | O9: number | Q9: 10 | U9: NN | W9: 1: 교촌에프앤비
B10: 1 | C10: userId | K10: 등록자ID | O10: varchar | Q10: 20 | W10: OMS_ADMIN 고정
B11: 1 | C11: reqList | K11: 요청리스트
B12: 2 | D12: ifKey | K12: IF 키 | O12: varchar | Q12: 50 | S12: O | U12: NN | W12: WMS와 OMS의 유니크 키
B13: 2 | D13: centerSeq | K13: 센터코드 | O13: number | Q13: 10 | U13: NN
B14: 2 | D14: regionCd | K14: 권역코드 | O14: varchar | Q14: 50 | U14: NN
B15: 2 | D15: ifContId | K15: 주문처ID | O15: varchar | Q15: 50 | U15: NN | W15: 거래처_ID
B16: 2 | D16: reqTypeCd | K16: 요청유형코드 | O16: varchar | Q16: 50 | S16: O | U16: NN | W16: 반품유형코드 RT01(출하반품)
B17: 2 | D17: reqYmd | K17: 반품요청일 | O17: varchar | Q17: 8 | U17: NN | W17: 양식: yyyymmdd
B18: 2 | D18: reqUserNm | K18: 반품요청자명 | O18: varchar | Q18: 100 | U18: NN
B19: 2 | D19: omsReqNo | K19: OMS_요청번호 | O19: varchar | Q19: 30 | U19: NN
B20: 2 | D20: note | K20: 비고 | O20: varchar | Q20: 1000
B21: 2 | D21: cdSalegrp | K21: 영업그룹 | O21: varchar | Q21: 7 | U21: NN
B22: 2 | D22: noEmp | K22: 영업담당자 | O22: varchar | Q22: 10 | U22: NN | W22: 영업사원 사번
B23: 2 | D23: tpSo | K23: 수주형태 | O23: varchar | Q23: 4 | U23: NN
B24: 2 | D24: prodList | K24: 품목리스트
B25: 3 | E25: ifIdx | K25: I/F 서브키 | O25: varchar | Q25: 20 | S25: O | U25: NN | W25: 해당 요청건의 유니크 키
B26: 3 | E26: ifProdId | K26: 품목번호 | O26: varchar | Q26: 50 | U26: NN
B27: 3 | E27: reqQty | K27: 요청수량 | O27: number | Q27: 10 | U27: NN
B28: 3 | E28: expYmd | K28: 소비기한 | O28: varchar | Q28: 8 | W28: 양식: yyyyMMdd
B29: 3 | E29: lotNo | K29: LOT NO | O29: varchar | Q29: 30 | W29: 매입 업체의 거래처번호
B30: 3 | E30: price | K30: 단가 | O30: number | Q30: 10
B31: 3 | E31: tax | K31: 세액 | O31: number | Q31: 10
B32: 3 | E32: cdExch | K32: 환종 | O32: varchar | Q32: 3 | U32: NN | W32: 000
B33: 3 | E33: rtExch | K33: 환율 | O33: number | Q33: 5 | U33: NN | W33: 1
B34: 3 | E34: tpVat | K34: 부가세율 | O34: varchar | Q34: 3 | U34: NN
B35: 3 | E35: fgVat | K35: 부가세코드 | O35: varchar | Q35: 3 | U35: NN
B37: Response
B38: LV | C38: 항목 | K38: 항목명 | O38: Type | Q38: SIZE | S38: KEY | U38: Null | W38: 설명
B39: 1 | C39: wmsResult | K39: WMS 처리 결과 | O39: varchar | Q39: 20 | U39: NN | W39: OK : 성공, NG : 실패
B40: 1 | C40: wmsMessage | K40: 메세지 | O40: varchar | Q40: 4000 | U40: NN | W40: 에러메세지
B41: 1 | C41: resList | K41: 요청리스트
B42: 2 | D42: ifKey | K42: IF 키 | O42: varchar | Q42: 20 | S42: O | U42: NN | W42: WMS와 OMS의 유니크 키
...

Sheet 반품_반품마감_ERP
A2: 인터페이스명 | B2: 반품마감
A3: 인터페이스 개요
A4: 인터페이스 상세 | B4: 1. WMS 연동 (WMS → ERP)
A5: Description | B5: IF테이블은 WMS DB 스키마에 생성 및 데이터 관리 ERP에서 WMS DB에 직접 접근해 데이터 입력함
A9: 인터페이스 유형 | I9: 적용방식 | J9: DB2DB
A10: 발생주기 | I10: 1일 발생 건수
A11: SOURCE | I11: TARGET
A12: 시스템 | B12: WMS | I12: 시스템 | J12: ERP
A13: INPUT | I13: INPUT
A14: Table Name | B14: Field | C14: Data Type | D14: PK | E14: Null | F14: Default Value | G14: Description | H14: 비고 | I14: Table Name | J14: Field | K14: Data Type | L14: PK | M14: Null | N14: Default Value | O14: Description | P14: 비고
G15: 생성순번(IDENTITY) | H15: 최초 1, 데이터 INSERT 될때마다, MAX+1 | I15: SA_Z_KCFNB_GI_PROC_IF | J15: seq | K15: BIGINT | L15: PK | M15: NN | O15: 생성순번(IDENTITY)
G16: 신규,수정/삭제 (A/D) | H16: A : 생성 데이터 insert 시 D : 데이터 삭제 시 | I16: SA_Z_KCFNB_GI_PROC_IF | J16: AUDType | K16: CHAR(1) | M16: NN | O16: 신규,수정/삭제 (A/D)
H17: 디폴트 1000으로 셋팅 | I17: SA_Z_KCFNB_GI_PROC_IF | J17: CD_COMPANY | K17: NVARCHAR(7) | L17: PK | M17: NN | N17: 1000 | O17: 회사코드 | P17: Default
H18: 디폴트 1000으로 셋팅 | I18: SA_Z_KCFNB_GI_PROC_IF | J18: CD_PLANT | K18: NVARCHAR(7) | L18: PK | M18: NN | N18: 1000 | O18: 공장코드 | P18: Default
A19: WMS_RETURN | B19: return_no | C19: varchar(30) | E19: NN | G19: 반품_번호 | H19: WMS 반품 업무번호 | I19: SA_Z_KCFNB_GI_PROC_IF | J19: NO_POS | K19: NVARCHAR(20) | L19: PK | M19: NN | O19: 연동번호 | P19: WMS 출하번호 판매반품일 경우 WMS 반품번호
H20: insert 시 품목순번 채번하여 입력 | I20: SA_Z_KCFNB_GI_PROC_IF | J20: NO_POS_LINE | K20: NUMERIC(5, 0) | L20: PK | M20: NN | O20: 연동항번 | P20: WMS 품목라인번호SEQ
A21: WMS_RETURN | B21: req_ymd | C21: varchar(8) | E21: NN | G21: 예정_연월일(반품) | I21: SA_Z_KCFNB_GI_PROC_IF | J21: DT_SO | K21: NVARCHAR(8) | M21: NN | O21: 주문일자 | P21: OMS 기준 주문일자 OMS 반품주문 등록일자
A22: WMS_RETURN | B22: cont_seq | C22: int4 | G22: 거래처_SEQ | H22: 거래처SEQ => 거래처ID 변환 후 입력 | I22: SA_Z_KCFNB_GI_PROC_IF | J22: CD_PARTNER | K22: NVARCHAR(20) | M22: NN | O22: 거래처코드 | P22: 가맹점 코드
A23: WMS_RETURN_PROD | B23: erp_exch_cd | C23: VARCHAR(3) | G23: ERP 환종 | H23: 반품예정 OMS IF 수신 가능 확인 필요 | I23: SA_Z_KCFNB_GI_PROC_IF | J23: CD_EXCH | K23: NVARCHAR(3) | M23: NN | N23: 000 | O23: 환종 | P23: Default 값 OMS에서 못주면 디폴트 셋팅
A24: WMS_RETURN_PROD | B24: erp_exch_rt | C24: int4 | G24: ERP 환율 | H24: 반품예정 OMS IF 수신 가능 확인 필요 | I24: SA_Z_KCFNB_GI_PROC_IF | J24: RT_EXCH | K24: NUMERIC(5, 0) | M24: NN | N24: 1.0000 | O24: 환율 | P24: Default 값 OMS에서 못주면 디폴트 셋팅
A25: WMS_RETURN | B25: erp_salegrp_cd | G25: ERP 영업그룹 | H25: 반품예정 OMS IF 수신 가능 확인 필요 | I25: SA_Z_KCFNB_GI_PROC_IF | J25: CD_SALEGRP | K25: NVARCHAR(7) | M25: NN | O25: 영업그룹 | P25: OMS 참조값
A26: WMS_RETURN | B26: erp_emp_no | C26: VARCHAR(10) | G26: ERP 영업담당자 사번 | H26: 반품예정 OMS IF 수신 가능 확인 필요 | I26: SA_Z_KCFNB_GI_PROC_IF | J26: NO_EMP | K26: NVARCHAR(10) | M26: NN | O26: 영업담당자 | P26: OMS 참조, 영업사원 사번
A27: WMS_RETURN | B27: erp_so_tp | C27: VARCHAR(4) | G27: ERP 수주형태 | H27: 반품예정 OMS IF 수신 가능 확인 필요 | I27: SA_Z_KCFNB_GI_PROC_IF | J27: TP_SO | K27: NVARCHAR(4) | M27: NN | O27: 수주형태 | P27: OMS 참조값 정상판매출고, 판매출고랑 다를거임
H28: 디폴트 Y로 셋팅 | I28: SA_Z_KCFNB_GI_PROC_IF | J28: YN_RETURN | K28: NVARCHAR(3) | M28: NN | N28: N | O28: 반품여부 | P28: 정상출하 "N",반품출하 "Y" 정상판매출고, 판매출고랑 다를거임
A29: WMS_RETURN_PROD | B29: prod_seq | C29: VARCHAR(50) | E29: NN | G29: 품목SEQ | H29: IF_PROD_ID로 컨버팅 후 입력 | I29: SA_Z_KCFNB_GI_PROC_IF | J29: CD_ITEM | K29: NVARCHAR(20) | M29: NN | O29: 품목코드 | P29: 품목코드
H30: WMS 반품처리 창고의 ERP IF 창고 코드 조회 후 삽입 | I30: SA_Z_KCFNB_GI_PROC_IF | J30: CD_SL | K30: NVARCHAR(7) | M30: NN | O30: 창고코드 | P30: 출고창고코드
A31: WMS_RETURN_PROD | B31: ex_qty | C31: decimal(10,2) | E31: NN | G31: 기처리_수량(반품) | I31: SA_Z_KCFNB_GI_PROC_IF | J31: QT_SO | K31: NUMERIC(17, 4) | M31: NN | O31: 주문수량(확정) | P31: 출하수량
A32: WMS_RETURN_PROD | B32: price | C32: decimal(10,2) | E32: NN | G32: 단가 | I32: SA_Z_KCFNB_GI_PROC_IF | J32: UM_SO | K32: NUMERIC(17, 4) | M32: NN | O32: 단가 | P32: OMS 참조데이터
H33: WMS에서 계산 후 입력(단가 * 처리수량) | I33: SA_Z_KCFNB_GI_PROC_IF | J33: AM_WONAMT | K33: NUMERIC(17, 4) | M33: NN | O33: 공급가액
A34: WMS_RETURN_PROD | B34: tax | C34: decimal(10,2) | E34: NN | G34: 세액 | I34: SA_Z_KCFNB_GI_PROC_IF | J34: AM_VAT | K34: NUMERIC(17, 4) | M34: NN | O34: 부가세 | P34: OMS 참조데이터
A35: WMS_RETURN_PROD | B35: erp_vat_tp | C35: VARCHAR(3) | G35: ERP 부가세율 | H35: 반품예정 OMS IF 수신 가능 확인 필요 | I35: SA_Z_KCFNB_GI_PROC_IF | J35: TP_VAT | K35: NVARCHAR(3) | M35: NN | O35: 부가세율 | P35: OMS 참조데이터
A36: WMS_RETURN_PROD | B36: erp_vat_fg | C36: VARCHAR(3) | G36: ERP 부가세코드 | H36: 반품예정 OMS IF 수신 가능 확인 필요 | I36: SA_Z_KCFNB_GI_PROC_IF | J36: FG_VAT | K36: NVARCHAR(3) | M36: NN | O36: 부가세코드 | P36: OMS 참조데이터
H37: 디폴트 WMS로 셋팅 | I37: SA_Z_KCFNB_GI_PROC_IF | J37: FG_DATA | K37: NVARCHAR(10) | M37: NN | O37: 연동구분 | P37: 입력시스템구분 "OMS", "WMS" 어디에서 수불처리를 했는지(WMS에서 처리)
A38: WMS_RETURN_TRAN | B38: proc_ymd | C38: varchar(8) | G38: 처리_연월일(반품) | H38: 품목별 처리일자 그룹핑 후 MAX값으로 전달 | I38: SA_Z_KCFNB_GI_PROC_IF | J38: DT_DUEDATE | K38: NVARCHAR(8) | M38: NN | O38: 배송일자 | P38: WMS : 출하일자 / OMS : 배송요청일 반품처리일자
H39: 디폴트 N으로 셋팅 | I39: SA_Z_KCFNB_GI_PROC_IF | J39: FG_STAT | K39: NVARCHAR(3) | M39: NN | N39: N | O39: 처리상태 | P39: N : 검토전(연동시스템 디폴트값) Y : 처리완료(ERP UPDATE) P : 검토완료(ERP UPDATE) E : 오류(ERP UPDATE)
H40: 디폴트 null로 셋팅 | I40: SA_Z_KCFNB_GI_PROC_IF | J40: ERR_MSG | K40: TEXT() | O40: 에러메세지 | P40: FG_STAT = 'E' 일 경우 에러메세지
H41: insert 시 getdate() 입력 | I41: SA_Z_KCFNB_GI_PROC_IF | J41: DTS_INSERT | K41: NVARCHAR(14) | O41: 입력일시 | P41: sysdate
H42: 마감처리한 유저의 사번으로 입력 | I42: SA_Z_KCFNB_GI_PROC_IF | J42: ID_INSERT | K42: NVARCHAR(15) | O42: 입력자 | P42: 사번
H43: 디폴트 null로 셋팅 | I43: SA_Z_KCFNB_GI_PROC_IF | J43: DTS_UPDATE | K43: NVARCHAR(14) | O43: 수정일시 | P43: sysdate
H44: 디폴트 null로 셋팅 | I44: SA_Z_KCFNB_GI_PROC_IF | J44: ID_UPDATE | K44: NVARCHAR(15) | O44: 수정자 | P44: 사번
...

Sheet 반품_반품마감_OMS
A1: 목록
B2: IF명 | E2: =ERP_인터페이스목록!C12 -> 반품마감_OMS | O2: ifId | R2: =ERP_인터페이스목록!G12 -> W2O_RT_CFM
B3: URI | E3: =ERP_인터페이스목록!J12 -> /{bizSeq}/sif/w2o/rt/cfm
B4: HTTP Method | E4: =ERP_인터페이스목록!L12 -> POST | O4: Data Type | R4: JSON
B5: SOURCE | E5: =ERP_인터페이스목록!D12 -> WMS | O5: TARGET | R5: =ERP_인터페이스목록!E12 -> OMS
B7: Request
B8: LV | C8: 항목 | K8: 항목명 | O8: Type | Q8: SIZE | S8: KEY | U8: Null | W8: 설명
B9: 1 | C9: bizSeq | K9: 사업장SEQ | O9: number | Q9: 10 | U9: NN | W9: 1: 교촌에프앤비
B10: 1 | C10: userId | K10: 등록자ID | O10: varchar | Q10: 20 | U10: NN | W10: 타시스템ID/WMS사용자 ID
B11: 1 | C11: userNm | K11: 등록자명 | O11: varchar | Q11: 100 | U11: NN | W11: WMS사용자명
B12: 1 | C12: procYmd | K12: 처리일자 | O12: varchar | Q12: 8 | U12: NN | W12: 양식: yyyyMMdd
B13: 1 | C13: procHms | K13: 처리시분초 | O13: varchar | Q13: 6 | U13: NN | W13: 양식: hhmmss
B14: 1 | C14: reqList | K14: 요청리스트
B15: 2 | D15: ifKey | K15: IF 키 | O15: varchar | Q15: 20 | S15: O | U15: NN | W15: WMS와 OMS의 유니크 키
B16: 2 | D16: reqTypeCd | K16: 요청유형코드 | O16: varchar | Q16: 50 | S16: O | U16: NN | W16: 반품유형코드 RT01(출하반품)
B17: 2 | D17: omsReqNo | K17: OMS_요청번호 | O17: varchar | Q17: 30
B18: 2 | D18: procYmd | K18: 처리일자 | O18: varchar | Q18: 8 | U18: NN | W18: 양식: yyyyMMdd
B19: 2 | D19: procHms | K19: 처리시분초 | O19: varchar | Q19: 6 | U19: NN | W19: 양식: hhmmss
B21: Response
B22: LV | C22: 항목 | K22: 항목명 | O22: Type | Q22: SIZE | S22: KEY | U22: Null | W22: 설명
B23: 1 | C23: wmsResult | K23: WMS 처리 결과 | O23: varchar | Q23: 20 | U23: NN | W23: OK : 성공, NG : 실패
B24: 1 | C24: wmsMessage | K24: 메세지 | O24: varchar | Q24: 4000 | U24: NN | W24: 에러메세지
B25: 1 | C25: resList | K25: 결과리스트
B26: 2 | D26: ifKey | K26: IF 키 | O26: varchar | Q26: 20 | S26: O | U26: NN | W26: WMS와 ERP의 유니크 키
B27: 2 | D27: reqTypeCd | K27: 요청유형코드 | O27: varchar | Q27: 50 | S27: O | U27: NN | W27: 반품유형코드 RT01(출하반품)
B28: 2 | D28: result | K28: 처리 여부 | O28: varchar | Q28: 1 | U28: NN | W28: OK : 성공, NG : 실패
B29: 2 | D29: message | K29: 처리메세지 | O29: varchar | Q29: 100 | W29: 처리 실패시 실패 사유
B31: 비고

Sheet 예외출고_등록
A2: 인터페이스명 | B2: 예외출고_등록
A3: 인터페이스 개요
A4: 인터페이스 상세 | B4: 1. ERP 연동 (ERP → WMS)
A5: Description | B5: WMS에서 ERP DB 접근하여 데이터 추출 계정대체_등록(삭제) / 재고이동_등록(삭제) / 구매반품_등록(삭제) 6개의 API 통합하여 관리 ERP의 재고이동요청/출고요청/매입반품의뢰
A9: 인터페이스 유형 | I9: 적용방식 | J9: DB2DB
A10: 발생주기 | I10: 1일 발생 건수
A11: SOURCE | I11: TARGET
A12: 시스템 | B12: ERP | I12: 시스템 | J12: WMS
A13: INPUT | I13: INPUT
A14: Table Name | B14: Field | C14: Data Type | D14: PK | E14: Null | F14: Default Value | G14: Description | H14: 비고 | I14: Table Name | J14: Field | K14: Data Type | L14: PK | M14: Null | N14: Default Value | O14: Description | P14: 비고
A15: MM_Z_KCFNB_GIREQ_IF | B15: Seq | C15: BIGINT | D15: PK | E15: NN | G15: 생성순번(IDENTITY) | H15: 최초 1, 데이터 INSERT 될때마다, MAX+1
A16: MM_Z_KCFNB_GIREQ_IF | B16: AUDType | C16: CHAR(1) | E16: NN | G16: 신규,수정/삭제 (A/D) | H16: A : 생성 데이터 insert 시 D : PU_RCV(H/L) 데이터 삭제 시
A17: MM_Z_KCFNB_GIREQ_IF | B17: CrtDateTime | C17: DATETIME | E17: NN | G17: 생성일시 | H17: insert 시점의 sysdate
A18: MM_Z_KCFNB_GIREQ_IF | B18: RecvYn | C18: CHAR(1) | F18: N | G18: 수신여부 (Y/N) | H18: WMS 미수신 = N WMS 수신 = Y WMS 처리중 또는 처리완료 = P (ERP 수정불가) 에러 = E
A19: MM_Z_KCFNB_GIREQ_IF | B19: RecvDateTime | C19: DATETIME | G19: 수신일시 | H19: WMS 데이터 수신 후 getdate()로 업데이트 처리
A20: MM_Z_KCFNB_GIREQ_IF | B20: BizSeq | C20: INT | E20: NN | G20: 사업장 SEQ | H20: 1: 교촌에프앤비 | I20: WMS_INVEN_ETC | J20: biz_seq | K20: INT
A21: MM_Z_KCFNB_GIREQ_IF | B21: sif_err_msg | C21: TEXT | G21: 에러메세지
A22: MM_Z_KCFNB_GIREQ_IF | B22: reg_id | C22: VARCHAR(20) | E22: NN | G22: 등록자ID | H22: 최초 등록자(사용자I/F 의 UserID) | I22: WMS_INVEN_ETC | J22: reg_id | K22: VARCHAR(20)
A23: MM_Z_KCFNB_GIREQ_IF | B23: reg_dt | C23: DATETIME | E23: NN | G23: 등록일 | H23: 최초 등록일시 | I23: WMS_INVEN_ETC | J23: reg_dt | K23: DATETIME
A24: MM_Z_KCFNB_GIREQ_IF | B24: mod_id | C24: VARCHAR(20) | G24: 수정자ID | H24: 데이터 최종수정자(사용자I/F 의 UserID) | I24: WMS_INVEN_ETC | J24: mod_id | K24: VARCHAR(20)
A25: MM_Z_KCFNB_GIREQ_IF | B25: mod_dt | C25: DATETIME | G25: 수정일 | H25: 데이터 최종수정일시 | I25: WMS_INVEN_ETC | J25: mod_dt | K25: DATETIME
I26: WMS_INVEN_ETC | J26: if_key | K26: VARCHAR(50) | L26: PK | M26: NN | O26: IF 키 | P26: ERP의 요청번호(NO_GIREQ) 셋팅
I27: WMS_INVEN_ETC_PROD | J27: if_idx | K27: VARCHAR(20) | L27: PK | M27: NN | O27: I/F 서브키 | P27: ERP의 요청항번(NO_LINE) 셋팅
A28: MM_Z_KCFNB_GIREQ_IF | B28: CD_COMPANY | C28: NVARCHAR(7) | D28: PK | E28: NN | F28: 1000 | G28: 회사코드 | H28: 예외출고 마감 시 ERP 전달용 | I28: WMS_INVEN_ETC | J28: erp_company_cd | K28: VARCHAR(7) | M28: NN | O28: ERP 회사코드 | P28: 신규컬럼 추가
A29: MM_Z_KCFNB_GIREQ_IF | B29: CD_BIZAREA | C29: NVARCHAR(7) | D29: PK | F29: 1000 | G29: 사업장코드 | H29: 예외출고 마감 시 ERP 전달용 | I29: WMS_INVEN_ETC | J29: erp_bizarea_cd | K29: VARCHAR(7) | M29: NN | O29: ERP 사업장코드 | P29: 신규컬럼 추가
A30: MM_Z_KCFNB_GIREQ_IF | B30: CD_PLANT | C30: NVARCHAR(7) | D30: PK | F30: 1000 | G30: 공장코드 | H30: 예외출고 마감 시 ERP 전달용 | I30: WMS_INVEN_ETC | J30: erp_plant_cd | K30: VARCHAR(7) | M30: NN | O30: ERP 공장코드 | P30: 신규컬럼 추가
I31: WMS_INVEN_ETC | J31: etc_type_cd | K31: VARCHAR(50) | L31: PK | M31: NN | O31: 요청유형코드 | P31: ERP의 수불구분(FG_IO)/대체유형(FG_GI) 기준으로 셋팅 012:계정대체 / 대체유형 { EX01(폐기), EX03(판매촉진비), EX05(연구개발비), EX07(소모품비), EX09(신규교육), EX11(보수교육), EX13(견본비), EX15(현물기부) } 재고이동(022) { EX31(원자재외주창고이동) } 구매반품(030) { EX95(구매반품) }
A32: MM_Z_KCFNB_GIREQ_IF | B32: NO_GIREQ | C32: NVARCHAR(20) | D32: PK | E32: NN | G32: 요청번호 | H32: 예외출고 마감 시 ERP 전달용 | I32: WMS_INVEN_ETC | J32: req_no | K32: VARCHAR(30) | M32: NN | O32: ERP_요청번호
A33: MM_Z_KCFNB_GIREQ_IF | B33: NO_LINE | C33: NUMERIC(5,0) | D33: PK | E33: NN | G33: 요청항번 | H33: 예외출고 마감 시 ERP 전달용 | I33: WMS_INVEN_ETC_PROD | J33: erp_line_no | K33: INT | O33: ERP 요청항번 | P33: D1에 신규컬럼 추가 필요
A34: MM_Z_KCFNB_GIREQ_IF | B34: NO_PO | C34: NVARCHAR(20) | F34: NULL | G34: 발주번호 | H34: 예외출고 마감 시 ERP 전달용 매입반품의뢰 시 값 INSERT, 그 외 NULL | I34: WMS_INVEN_ETC_PROD | J34: erp_po_no | K34: VARCHAR(20) | O34: ERP 발주번호 | P34: D1에 신규컬럼 추가 필요
A35: MM_Z_KCFNB_GIREQ_IF | B35: NO_POLINE | C35: NUMERIC(5,0) | F35: 0 | G35: 발주항번 | H35: 예외출고 마감 시 ERP 전달용 매입반품의뢰 시 값 INSERT, 그 외 0 | I35: WMS_INVEN_ETC_PROD | J35: erp_poline_no | K35: INT | O35: ERP 발주항번 | P35: D1에 신규컬럼 추가 필요
I36: WMS_INVEN_ETC | J36: center_seq | K36: INT | M36: NN | O36: 센터SEQ | P36: ERP창고코드(FROM) 기준으로 센터정보 셋팅 "센터정보" 시트 참조
A37: MM_Z_KCFNB_GIREQ_IF | B37: CD_SL | C37: NVARCHAR(7) | G37: 창고코드(FROM) | H37: 예외출고 마감 시 ERP 전달용 출고창고 | I37: WMS_INVEN_ETC | J37: erp_wh_cd | K37: VARCHAR(50) | M37: NN | O37: 예외출고처 | P37: ERP 출고창고
A38: MM_Z_KCFNB_GIREQ_IF | B38: CD_GRSL | C38: NVARCHAR(7) | F38: NULL | G38: 창고코드(TO) | H38: 예외출고 마감 시 ERP 전달용 재고이동일 경우 입고창고 INSERT, 그 외 NULL | I38: WMS_INVEN_ETC | J38: erp_grsl_cd | K38: VARCHAR(7) | O38: 이동창고(TO) | P38: 신규컬럼 추가 필요 ERP의 재고이동(수도권센터 ->원자재외부센터) 처리 시 to창고
