Workbook
Name _TMP_C1: #REF!
Name A: #REF!
Name cause: #REF!
Name Comments: #REF!
Name DD: #REF!
Name Ltst_TestLog: "'Test log'"
Name Severity: #REF!
Name State_of_Origin: #REF!
Name Tablelayout: #REF!
Name West_visit_cnt: #REF!
Name ㅁ: #REF!
Name 분류: #REF!
Name 분류: #REF!

Sheet 표지
M4: WMS 구축 프로젝트
M7: 공통코드정의서

Sheet 개정이력
A1: 개 정 이 력
A3: 버전 | B3: 개정범위 | C3: 내용 | D3: 작성자 | E3: 일자
A4: v1.0 | B4: 최초작성 | C4: 초안 작성 | D4: 이택 | E4: 2026.01.01

Sheet 3.코드그룹
A2: 공통코드정의서
A3: 시스템명 | C3: WMS | D3: 서브시스템명
A4: 단계명 | C4: 구현 | D4: 작성일자 | E4: 46150 | F4: 버전 | I4: v2.0
A6: ■ 코드그룹
A7: 사업장 | B7: 그룹코드 | C7: 코드그룹명 | D7: 코드설명 | G7: 사용자코드 여부 | H7: 수불_유형_여부 | I7: 비고
A8: 1 | B8: AD_PROD_STS_CD | C8: 재고조정_품목_상태코드 | G8: N
A9: 1 | B9: AD_STS_CD | C9: 재고조정_상태_코드 | G9: N
A10: 1 | B10: AD_TYPE_CD | C10: 재고조정_유형 | G10: N | H10: AD
A11: 1 | B11: AUTH_TYPE_CD | C11: 권한_유형_코드 | G11: N
A12: 1 | B12: AVAILABLE_INVEN_YN | C12: 가용재고_여부 | G12: N
A13: 1 | B13: BARCODE_DIM_CD | C13: 바코드_차원_코드 | G13: N
A14: 1 | B14: BARCODE_TYPE_CD | C14: 바코드_유형_코드 | G14: N
A15: 1 | B15: BIZ_DIV_CD | C15: 사업장_구분 | G15: N
A16: 1 | B16: BOARD_CAT_CD | C16: 게시판_카테고리_코드 | G16: N
A17: 1 | B17: BOX_TYPE_CD | C17: 박스유형 | G17: N
A18: 1 | B18: CAR_DIV_CD | C18: 차량구분 | G18: N
A19: 1 | B19: CAR_TYPE_CD | C19: 차량유형 | G19: N
A20: 1 | B20: CFD_CD | C20: 냉장냉동상온_코드(창고) | G20: N
A21: 1 | B21: CFM_YN | C21: 확정여부 | G21: N
A22: 1 | B22: CONT_DIV_CD | C22: 거래처_구분_코드 | G22: N
... A43: 1 | B43: INWH_STS_CD | C43: 입고_상태_코드 | G43: N
A44: 1 | B44: INWH_TYPE_CD | C44: 입고_유형_코드 | G44: N | H44: IW
A45: 1 | B45: LABEL_PAPER_DIV_CD | C45: 용지_구분_코드 | G45: N
A46: 1 | B46: LABEL_PAPER_TYPE_CD | C46: 용지_유형_코드 | G46: N
A47: 1 | B47: LARGE_CD | C47: 품목_대분류_코드 | G47: Y
A48: 1 | B48: LOAD_PROD_STS_CD | C48: 상차_품목_상태_코드 | G48: N
A49: 1 | B49: LOAD_STS_CD | C49: 상차_상태_코드 | G49: N
A50: 1 | B50: LOC_MNG_CD | C50: 위치_담당자_코드 | G50: Y
A51: 1 | B51: LOCK_YN | C51: 잠금_여부 | G51: N
A52: 1 | B52: LOG_CONN_TYPE_CD | C52: 로그_접근_유형_코드 | G52: N
A53: 1 | B53: MENU_TYPE_CD | C53: 메뉴_유형_코드 | G53: N
A54: 1 | B54: MIDDLE_CD | C54: 품목_중분류_코드 | G54: Y
A55: 1 | B55: MV_PROD_STS_CD | C55: 재고이동_품목_상태_코드 | G55: N
A56: 1 | B56: MV_STS_CD | C56: 재고이동_상태_코드 | G56: N
A57: 1 | B57: MV_TYPE_CD | C57: 재고이동_유형 | G57: N | H57: IM
A58: 1 | B58: ORDER_TYPE_CD | C58: 주문_유형_코드 | G58: N
A59: 1 | B59: ORIGIN_CD | C59: 원산지_코드 | G59: N
A60: 1 | B60: OUTBIZ_PROC_TYPE_CD | C60: 출하_처리_타입_코드 | G60: N
A61: 1 | B61: OUTBIZ_PROD_STS_CD | C61: 출하_품목_상태_코드 | G61: N
A62: 1 | B62: OUTBIZ_STS_CD | C62: 출하_상태_코드 | G62: N
...

Sheet 4.상세코드
A1: ■ 상세코드
A2: 사업장 | B2: 그룹코드 | C2: 코드 | D2: 코드명 | E2: 참조상위코드 | F2: 참조코드 | G2: 순서 | H2: 표시여부 | I2: 사용여부
A3: BIZ_SEQ | B3: COMM_H_CD | C3: COMM_D_CD | D3: COMM_D_NM | E3: REF_H_CD | F3: REF_D_CD | G3: DISP_IDX | H3: DISP_YN | I3: USE_YN
A4: 1 | B4: AD_PROD_STS_CD | C4: 11 | D4: 예정 | G4: 1 | H4: Y | I4: Y
A5: 1 | B5: AD_PROD_STS_CD | C5: 55 | D5: 처리중 | G5: 2 | H5: Y | I5: Y
A6: 1 | B6: AD_PROD_STS_CD | C6: 77 | D6: 확정 | G6: 3 | H6: Y | I6: Y
A7: 1 | B7: AD_STS_CD | C7: 11 | D7: 예정 | G7: 1 | H7: Y | I7: Y
A8: 1 | B8: AD_STS_CD | C8: 55 | D8: 처리중 | G8: 2 | H8: Y | I8: Y
A9: 1 | B9: AD_STS_CD | C9: 77 | D9: 확정 | G9: 3 | H9: Y | I9: Y
A10: 1 | B10: AD_TYPE_CD | C10: AD01 | D10: 실사조정 | E10: INOUT_TYPE_CD | F10: AD | G10: 1 | H10: Y | I10: Y
A11: 1 | B11: AD_TYPE_CD | C11: AD91 | D11: 기타조정 | E11: INOUT_TYPE_CD | F11: AD | G11: 2 | H11: Y | I11: Y
A12: 1 | B12: AD_TYPE_CD | C12: AD99 | D12: 기초조정 | E12: INOUT_TYPE_CD | F12: AD | G12: 3 | H12: Y | I12: Y
A13: 1 | B13: AUTH_TYPE_CD | C13: S | D13: 관리자 | G13: 1 | H13: Y | I13: Y
A14: 1 | B14: AUTH_TYPE_CD | C14: B | D14: 사업장 | G14: 2 | H14: Y | I14: Y
A15: 1 | B15: AUTH_TYPE_CD | C15: C | D15: 센터 | G15: 3 | H15: Y | I15: Y
A16: 1 | B16: AVAILABLE_INVEN_YN | C16: Y | D16: 가용 | G16: 1 | H16: Y | I16: Y
A17: 1 | B17: AVAILABLE_INVEN_YN | C17: N | D17: 비가용 | G17: 2 | H17: Y | I17: Y
A18: 1 | B18: BARCODE_DIM_CD | C18: 1D | D18: 1D | G18: 1 | H18: Y | I18: Y
A19: 1 | B19: BARCODE_DIM_CD | C19: 2D | D19: 2D | G19: 2 | H19: Y | I19: Y
A20: 1 | B20: BARCODE_DIM_CD | C20: - | D20: 사용안함 | G20: 3 | H20: Y | I20: Y
A21: 1 | B21: BARCODE_TYPE_CD | C21: 2048 | D21: QR_CODE | E21: BARCODE_DIM_CD | F21: 2D | G21: 1 | H21: Y | I21: Y
A22: 1 | B22: BARCODE_TYPE_CD | C22: 16 | D22: CODE_128 | E22: BARCODE_DIM_CD | F22: 1D | G22: 2 | H22: Y | I22: Y
A23: 1 | B23: BARCODE_TYPE_CD | C23: 32 | D23: DATA_MATRIX | E23: BARCODE_DIM_CD | F23: 2D | G23: 3 | H23: Y | I23: Y
A24: 1 | B24: BIZ_DIV_CD | C24: OWN | D24: 자사물류 | G24: 1 | H24: Y | I24: Y
A25: 1 | B25: BIZ_DIV_CD | C25: TPL | D25: 물류대행 | G25: 2 | H25: Y | I25: Y
A26: 1 | B26: BIZ_DIV_CD | C26: SHIPPER | D26: 화주 | G26: 3 | H26: Y | I26: Y
A27: 1 | B27: BOARD_CAT_CD | C27: 1 | D27: 사용문의 | G27: 1 | H27: Y | I27: Y
A28: 1 | B28: BOARD_CAT_CD | C28: 2 | D28: 요금문의 | G28: 2 | H28: Y | I28: Y
A29: 1 | B29: BOARD_CAT_CD | C29: 3 | D29: 라벨용지 | G29: 3 | H29: Y | I29: Y
A30: 1 | B30: BOX_TYPE_CD | C30: 01 | D30: 극소 | G30: 1 | H30: Y | I30: Y
A31: 1 | B31: BOX_TYPE_CD | C31: 02 | D31: 소 | G31: 2 | H31: Y | I31: Y
A32: 1 | B32: BOX_TYPE_CD | C32: 03 | D32: 중 | G32: 3 | H32: Y | I32: Y
A33: 1 | B33: BOX_TYPE_CD | C33: 04 | D33: 대 | G33: 4 | H33: Y | I33: Y
A34: 1 | B34: BOX_TYPE_CD | C34: 05 | D34: 특대 | G34: 5 | H34: Y | I34: Y
A35: 1 | B35: BOX_TYPE_CD | C35: 06 | D35: 취급제한 | G35: 6 | H35: Y | I35: Y
... A180: 1 | B180: INWH_STS_CD | C180: 77 | D180: 확정 | G180: 3 | H180: Y | I180: Y
A181: 1 | B181: INWH_TYPE_CD | C181: IW01 | D181: 구매입고 | E181: INOUT_TYPE_CD | F181: IW | G181: 1 | H181: Y | I181: Y
A182: 1 | B182: INWH_TYPE_CD | C182: IW51 | D182: 예외입고 | E182: INOUT_TYPE_CD | F182: IW | G182: 2 | H182: Y | I182: Y
A183: 1 | B183: INWH_TYPE_CD | C183: IW91 | D183: 기타입고 | E183: INOUT_TYPE_CD | F183: IW | G183: 3 | H183: Y | I183: Y
A184: 1 | B184: LABEL_PAPER_DIV_CD | C184: SL | D184: SKU라벨 | G184: 1 | H184: Y | I184: Y
...

Sheet 그룹SQL
A1: =IF(ISBLANK('3.코드그룹'!H8), CONCATENATE(B1, '3.코드그룹'!A8, ",", "'", '3.코드그룹'!B8, "' ,'", '3.코드그룹'!C8,"', '", '3.코드그룹'!G8, "', ", "NULL", 그룹SQL!C1), CONCATENATE(B1, '3.코드그룹'!A8, ",", "'", '3.코드그룹'!B8, "' ,'", '3.코드그룹'!C8,"', '", '3.코드그룹'!G8, "', '", '3.코드그룹'!H8, "'", 그룹SQL!C1)) | B1: INSERT INTO SM_COMM_H (biz_seq, comm_h_cd, comm_h_nm, user_cd_yn, inout_cd, use_yn, reg_dt, reg_id) VALUES ( | C1: ,'Y', getDate(), 'administrator' );
A2: =IF(ISBLANK('3.코드그룹'!H9), CONCATENATE(B2, '3.코드그룹'!A9, ",", "'", '3.코드그룹'!B9, "' ,'", '3.코드그룹'!C9,"', '", '3.코드그룹'!G9, "', ", "NULL", 그룹SQL!C2), CONCATENATE(B2, '3.코드그룹'!A9, ",", "'", '3.코드그룹'!B9, "' ,'", '3.코드그룹'!C9,"', '", '3.코드그룹'!G9, "', '", '3.코드그룹'!H9, "'", 그룹SQL!C2)) | B2: INSERT INTO SM_COMM_H (biz_seq, comm_h_cd, comm_h_nm, user_cd_yn, inout_cd, use_yn, reg_dt, reg_id) VALUES ( | C2: ,'Y', getDate(), 'administrator' );
A3: =IF(ISBLANK('3.코드그룹'!H10), CONCATENATE(B3, '3.코드그룹'!A10, ",", "'", '3.코드그룹'!B10, "' ,'", '3.코드그룹'!C10,"', '", '3.코드그룹'!G10, "', ", "NULL", 그룹SQL!C3), CONCATENATE(B3, '3.코드그룹'!A10, ",", "'", '3.코드그룹'!B10, "' ,'", '3.코드그룹'!C10,"', '", '3.코드그룹'!G10, "', '", '3.코드그룹'!H10, "'", 그룹SQL!C3)) | B3: INSERT INTO SM_COMM_H (biz_seq, comm_h_cd, comm_h_nm, user_cd_yn, inout_cd, use_yn, reg_dt, reg_id) VALUES ( | C3: ,'Y', getDate(), 'administrator' );
A4: =IF(ISBLANK('3.코드그룹'!H11), CONCATENATE(B4, '3.코드그룹'!A11, ",", "'", '3.코드그룹'!B11, "' ,'", '3.코드그룹'!C11,"', '", '3.코드그룹'!G11, "', ", "NULL", 그룹SQL!C4), CONCATENATE(B4, '3.코드그룹'!A11, ",", "'", '3.코드그룹'!B11, "' ,'", '3.코드그룹'!C11,"', '", '3.코드그룹'!G11, "', '", '3.코드그룹'!H11, "'", 그룹SQL!C4)) | B4: INSERT INTO SM_COMM_H (biz_seq, comm_h_cd, comm_h_nm, user_cd_yn, inout_cd, use_yn, reg_dt, reg_id) VALUES ( | C4: ,'Y', getDate(), 'administrator' );
A5: =IF(ISBLANK('3.코드그룹'!H12), CONCATENATE(B5, '3.코드그룹'!A12, ",", "'", '3.코드그룹'!B12, "' ,'", '3.코드그룹'!C12,"', '", '3.코드그룹'!G12, "', ", "NULL", 그룹SQL!C5), CONCATENATE(B5, '3.코드그룹'!A12, ",", "'", '3.코드그룹'!B12, "' ,'", '3.코드그룹'!C12,"', '", '3.코드그룹'!G12, "', '", '3.코드그룹'!H12, "'", 그룹SQL!C5)) | B5: INSERT INTO SM_COMM_H (biz_seq, comm_h_cd, comm_h_nm, user_cd_yn, inout_cd, use_yn, reg_dt, reg_id) VALUES ( | C5: ,'Y', getDate(), 'administrator' );
A6: =IF(ISBLANK('3.코드그룹'!H13), CONCATENATE(B6, '3.코드그룹'!A13, ",", "'", '3.코드그룹'!B13, "' ,'", '3.코드그룹'!C13,"', '", '3.코드그룹'!G13, "', ", "NULL", 그룹SQL!C6), CONCATENATE(B6, '3.코드그룹'!A13, ",", "'", '3.코드그룹'!B13, "' ,'", '3.코드그룹'!C13,"', '", '3.코드그룹'!G13, "', '", '3.코드그룹'!H13, "'", 그룹SQL!C6)) | B6: INSERT INTO SM_COMM_H (biz_seq, comm_h_cd, comm_h_nm, user_cd_yn, inout_cd, use_yn, reg_dt, reg_id) VALUES ( | C6: ,'Y', getDate(), 'administrator' );
A7: =IF(ISBLANK('3.코드그룹'!H14), CONCATENATE(B7, '3.코드그룹'!A14, ",", "'", '3.코드그룹'!B14, "' ,'", '3.코드그룹'!C14,"', '", '3.코드그룹'!G14, "', ", "NULL", 그룹SQL!C7), CONCATENATE(B7, '3.코드그룹'!A14, ",", "'", '3.코드그룹'!B14, "' ,'", '3.코드그룹'!C14,"', '", '3.코드그룹'!G14, "', '", '3.코드그룹'!H14, "'", 그룹SQL!C7)) | B7: INSERT INTO SM_COMM_H (biz_seq, comm_h_cd, comm_h_nm, user_cd_yn, inout_cd, use_yn, reg_dt, reg_id) VALUES ( | C7: ,'Y', getDate(), 'administrator' );
A8: =IF(ISBLANK('3.코드그룹'!H15), CONCATENATE(B8, '3.코드그룹'!A15, ",", "'", '3.코드그룹'!B15, "' ,'", '3.코드그룹'!C15,"', '", '3.코드그룹'!G15, "', ", "NULL", 그룹SQL!C8), CONCATENATE(B8, '3.코드그룹'!A15, ",", "'", '3.코드그룹'!B15, "' ,'", '3.코드그룹'!C15,"', '", '3.코드그룹'!G15, "', '", '3.코드그룹'!H15, "'", 그룹SQL!C8)) | B8: INSERT INTO SM_COMM_H (biz_seq, comm_h_cd, comm_h_nm, user_cd_yn, inout_cd, use_yn, reg_dt, reg_id) VALUES ( | C8: ,'Y', getDate(), 'administrator' );
A9: =IF(ISBLANK('3.코드그룹'!H16), CONCATENATE(B9, '3.코드그룹'!A16, ",", "'", '3.코드그룹'!B16, "' ,'", '3.코드그룹'!C16,"', '", '3.코드그룹'!G16, "', ", "NULL", 그룹SQL!C9), CONCATENATE(B9, '3.코드그룹'!A16, ",", "'", '3.코드그룹'!B16, "' ,'", '3.코드그룹'!C16,"', '", '3.코드그룹'!G16, "', '", '3.코드그룹'!H16, "'", 그룹SQL!C9)) | B9: INSERT INTO SM_COMM_H (biz_seq, comm_h_cd, comm_h_nm, user_cd_yn, inout_cd, use_yn, reg_dt, reg_id) VALUES ( | C9: ,'Y', getDate(), 'administrator' );
A10: =IF(ISBLANK('3.코드그룹'!H17), CONCATENATE(B10, '3.코드그룹'!A17, ",", "'", '3.코드그룹'!B17, "' ,'", '3.코드그룹'!C17,"', '", '3.코드그룹'!G17, "', ", "NULL", 그룹SQL!C10), CONCATENATE(B10, '3.코드그룹'!A17, ",", "'", '3.코드그룹'!B17, "' ,'", '3.코드그룹'!C17,"', '", '3.코드그룹'!G17, "', '", '3.코드그룹'!H17, "'", 그룹SQL!C10)) | B10: INSERT INTO SM_COMM_H (biz_seq, comm_h_cd, comm_h_nm, user_cd_yn, inout_cd, use_yn, reg_dt, reg_id) VALUES ( | C10: ,'Y', getDate(), 'administrator' );
A11: =IF(ISBLANK('3.코드그룹'!H18), CONCATENATE(B11, '3.코드그룹'!A18, ",", "'", '3.코드그룹'!B18, "' ,'", '3.코드그룹'!C18,"', '", '3.코드그룹'!G18, "', ", "NULL", 그룹SQL!C11), CONCATENATE(B11, '3.코드그룹'!A18, ",", "'", '3.코드그룹'!B18, "' ,'", '3.코드그룹'!C18,"', '", '3.코드그룹'!G18, "', '", '3.코드그룹'!H18, "'", 그룹SQL!C11)) | B11: INSERT INTO SM_COMM_H (biz_seq, comm_h_cd, comm_h_nm, user_cd_yn, inout_cd, use_yn, reg_dt, reg_id) VALUES ( | C11: ,'Y', getDate(), 'administrator' );
A12: =IF(ISBLANK('3.코드그룹'!H19), CONCATENATE(B12, '3.코드그룹'!A19, ",", "'", '3.코드그룹'!B19, "' ,'", '3.코드그룹'!C19,"', '", '3.코드그룹'!G19, "', ", "NULL", 그룹SQL!C12), CONCATENATE(B12, '3.코드그룹'!A19, ",", "'", '3.코드그룹'!B19, "' ,'", '3.코드그룹'!C19,"', '", '3.코드그룹'!G19, "', '", '3.코드그룹'!H19, "'", 그룹SQL!C12)) | B12: INSERT INTO SM_COMM_H (biz_seq, comm_h_cd, comm_h_nm, user_cd_yn, inout_cd, use_yn, reg_dt, reg_id) VALUES ( | C12: ,'Y', getDate(), 'administrator' );
... A93: =IF(ISBLANK('3.코드그룹'!H100), CONCATENATE(B93, '3.코드그룹'!A100, ",", "'", '3.코드그룹'!B100, "' ,'", '3.코드그룹'!C100,"', '", '3.코드그룹'!G100, "', ", "NULL", 그룹SQL!C93), CONCATENATE(B93, '3.코드그룹'!A100, ",", "'", '3.코드그룹'!B100, "' ,'", '3.코드그룹'!C100,"', '", '3.코드그룹'!G100, "', '", '3.코드그룹'!H100, "'", 그룹SQL!C93)) | B93: INSERT INTO SM_COMM_H (biz_seq, comm_h_cd, comm_h_nm, user_cd_yn, inout_cd, use_yn, reg_dt, reg_id) VALUES ( | C93: ,'Y', getDate(), 'administrator' );

Sheet 상세SQL
A1: =CONCATENATE(B1, '4.상세코드'!A4, ", '", '4.상세코드'!B4, "', '", '4.상세코드'!C4, "', '", '4.상세코드'!D4, "',", IF(ISBLANK('4.상세코드'!E4), "NULL", CONCATENATE("'", '4.상세코드'!E4, "'")), ",", IF(ISBLANK('4.상세코드'!F4), "NULL", CONCATENATE("'", '4.상세코드'!F4, "'")), ",", '4.상세코드'!G4, ", '", '4.상세코드'!H4, "', '", '4.상세코드'!I4, "'", 상세SQL!C1) | B1: INSERT INTO SM_COMM_D (biz_seq, comm_h_cd, comm_d_cd, comm_d_nm, ref_h_cd, ref_d_cd, disp_no, disp_yn, use_yn, reg_id, reg_dt) VALUES ( | C1: , 'administrator', getDate());
A2: =CONCATENATE(B2, '4.상세코드'!A5, ", '", '4.상세코드'!B5, "', '", '4.상세코드'!C5, "', '", '4.상세코드'!D5, "',", IF(ISBLANK('4.상세코드'!E5), "NULL", CONCATENATE("'", '4.상세코드'!E5, "'")), ",", IF(ISBLANK('4.상세코드'!F5), "NULL", CONCATENATE("'", '4.상세코드'!F5, "'")), ",", '4.상세코드'!G5, ", '", '4.상세코드'!H5, "', '", '4.상세코드'!I5, "'", 상세SQL!C2) | B2: INSERT INTO SM_COMM_D (biz_seq, comm_h_cd, comm_d_cd, comm_d_nm, ref_h_cd, ref_d_cd, disp_no, disp_yn, use_yn, reg_id, reg_dt) VALUES ( | C2: , 'administrator', getDate());
A3: =CONCATENATE(B3, '4.상세코드'!A6, ", '", '4.상세코드'!B6, "', '", '4.상세코드'!C6, "', '", '4.상세코드'!D6, "',", IF(ISBLANK('4.상세코드'!E6), "NULL", CONCATENATE("'", '4.상세코드'!E6, "'")), ",", IF(ISBLANK('4.상세코드'!F6), "NULL", CONCATENATE("'", '4.상세코드'!F6, "'")), ",", '4.상세코드'!G6, ", '", '4.상세코드'!H6, "', '", '4.상세코드'!I6, "'", 상세SQL!C3) | B3: INSERT INTO SM_COMM_D (biz_seq, comm_h_cd, comm_d_cd, comm_d_nm, ref_h_cd, ref_d_cd, disp_no, disp_yn, use_yn, reg_id, reg_dt) VALUES ( | C3: , 'administrator', getDate());
A4: =CONCATENATE(B4, '4.상세코드'!A7, ", '", '4.상세코드'!B7, "', '", '4.상세코드'!C7, "', '", '4.상세코드'!D7, "',", IF(ISBLANK('4.상세코드'!E7), "NULL", CONCATENATE("'", '4.상세코드'!E7, "'")), ",", IF(ISBLANK('4.상세코드'!F7), "NULL", CONCATENATE("'", '4.상세코드'!F7, "'")), ",", '4.상세코드'!G7, ", '", '4.상세코드'!H7, "', '", '4.상세코드'!I7, "'", 상세SQL!C4) | B4: INSERT INTO SM_COMM_D (biz_seq, comm_h_cd, comm_d_cd, comm_d_nm, ref_h_cd, ref_d_cd, disp_no, disp_yn, use_yn, reg_id, reg_dt) VALUES ( | C4: , 'administrator', getDate());
A5: =CONCATENATE(B5, '4.상세코드'!A8, ", '", '4.상세코드'!B8, "', '", '4.상세코드'!C8, "', '", '4.상세코드'!D8, "',", IF(ISBLANK('4.상세코드'!E8), "NULL", CONCATENATE("'", '4.상세코드'!E8, "'")), ",", IF(ISBLANK('4.상세코드'!F8), "NULL", CONCATENATE("'", '4.상세코드'!F8, "'")), ",", '4.상세코드'!G8, ", '", '4.상세코드'!H8, "', '", '4.상세코드'!I8, "'", 상세SQL!C5) | B5: INSERT INTO SM_COMM_D (biz_seq, comm_h_cd, comm_d_cd, comm_d_nm, ref_h_cd, ref_d_cd, disp_no, disp_yn, use_yn, reg_id, reg_dt) VALUES ( | C5: , 'administrator', getDate());
A6: =CONCATENATE(B6, '4.상세코드'!A9, ", '", '4.상세코드'!B9, "', '", '4.상세코드'!C9, "', '", '4.상세코드'!D9, "',", IF(ISBLANK('4.상세코드'!E9), "NULL", CONCATENATE("'", '4.상세코드'!E9, "'")), ",", IF(ISBLANK('4.상세코드'!F9), "NULL", CONCATENATE("'", '4.상세코드'!F9, "'")), ",", '4.상세코드'!G9, ", '", '4.상세코드'!H9, "', '", '4.상세코드'!I9, "'", 상세SQL!C6) | B6: INSERT INTO SM_COMM_D (biz_seq, comm_h_cd, comm_d_cd, comm_d_nm, ref_h_cd, ref_d_cd, disp_no, disp_yn, use_yn, reg_id, reg_dt) VALUES ( | C6: , 'administrator', getDate());
A7: =CONCATENATE(B7, '4.상세코드'!A10, ", '", '4.상세코드'!B10, "', '", '4.상세코드'!C10, "', '", '4.상세코드'!D10, "',", IF(ISBLANK('4.상세코드'!E10), "NULL", CONCATENATE("'", '4.상세코드'!E10, "'")), ",", IF(ISBLANK('4.상세코드'!F10), "NULL", CONCATENATE("'", '4.상세코드'!F10, "'")), ",", '4.상세코드'!G10, ", '", '4.상세코드'!H10, "', '", '4.상세코드'!I10, "'", 상세SQL!C7) | B7: INSERT INTO SM_COMM_D (biz_seq, comm_h_cd, comm_d_cd, comm_d_nm, ref_h_cd, ref_d_cd, disp_no, disp_yn, use_yn, reg_id, reg_dt) VALUES ( | C7: , 'administrator', getDate());
A8: =CONCATENATE(B8, '4.상세코드'!A11, ", '", '4.상세코드'!B11, "', '", '4.상세코드'!C11, "', '", '4.상세코드'!D11, "',", IF(ISBLANK('4.상세코드'!E11), "NULL", CONCATENATE("'", '4.상세코드'!E11, "'")), ",", IF(ISBLANK('4.상세코드'!F11), "NULL", CONCATENATE("'", '4.상세코드'!F11, "'")), ",", '4.상세코드'!G11, ", '", '4.상세코드'!H11, "', '", '4.상세코드'!I11, "'", 상세SQL!C8) | B8: INSERT INTO SM_COMM_D (biz_seq, comm_h_cd, comm_d_cd, comm_d_nm, ref_h_cd, ref_d_cd, disp_no, disp_yn, use_yn, reg_id, reg_dt) VALUES ( | C8: , 'administrator', getDate());
A9: =CONCATENATE(B9, '4.상세코드'!A12, ", '", '4.상세코드'!B12, "', '", '4.상세코드'!C12, "', '", '4.상세코드'!D12, "',", IF(ISBLANK('4.상세코드'!E12), "NULL", CONCATENATE("'", '4.상세코드'!E12, "'")), ",", IF(ISBLANK('4.상세코드'!F12), "NULL", CONCATENATE("'", '4.상세코드'!F12, "'")), ",", '4.상세코드'!G12, ", '", '4.상세코드'!H12, "', '", '4.상세코드'!I12, "'", 상세SQL!C9) | B9: INSERT INTO SM_COMM_D (biz_seq, comm_h_cd, comm_d_cd, comm_d_nm, ref_h_cd, ref_d_cd, disp_no, disp_yn, use_yn, reg_id, reg_dt) VALUES ( | C9: , 'administrator', getDate());
A10: =CONCATENATE(B10, '4.상세코드'!A13, ", '", '4.상세코드'!B13, "', '", '4.상세코드'!C13, "', '", '4.상세코드'!D13, "',", IF(ISBLANK('4.상세코드'!E13), "NULL", CONCATENATE("'", '4.상세코드'!E13, "'")), ",", IF(ISBLANK('4.상세코드'!F13), "NULL", CONCATENATE("'", '4.상세코드'!F13, "'")), ",", '4.상세코드'!G13, ", '", '4.상세코드'!H13, "', '", '4.상세코드'!I13, "'", 상세SQL!C10) | B10: INSERT INTO SM_COMM_D (biz_seq, comm_h_cd, comm_d_cd, comm_d_nm, ref_h_cd, ref_d_cd, disp_no, disp_yn, use_yn, reg_id, reg_dt) VALUES ( | C10: , 'administrator', getDate());
A11: =CONCATENATE(B11, '4.상세코드'!A14, ", '", '4.상세코드'!B14, "', '", '4.상세코드'!C14, "', '", '4.상세코드'!D14, "',", IF(ISBLANK('4.상세코드'!E14), "NULL", CONCATENATE("'", '4.상세코드'!E14, "'")), ",", IF(ISBLANK('4.상세코드'!F14), "NULL", CONCATENATE("'", '4.상세코드'!F14, "'")), ",", '4.상세코드'!G14, ", '", '4.상세코드'!H14, "', '", '4.상세코드'!I14, "'", 상세SQL!C11) | B11: INSERT INTO SM_COMM_D (biz_seq, comm_h_cd, comm_d_cd, comm_d_nm, ref_h_cd, ref_d_cd, disp_no, disp_yn, use_yn, reg_id, reg_dt) VALUES ( | C11: , 'administrator', getDate());
A12: =CONCATENATE(B12, '4.상세코드'!A15, ", '", '4.상세코드'!B15, "', '", '4.상세코드'!C15, "', '", '4.상세코드'!D15, "',", IF(ISBLANK('4.상세코드'!E15), "NULL", CONCATENATE("'", '4.상세코드'!E15, "'")), ",", IF(ISBLANK('4.상세코드'!F15), "NULL", CONCATENATE("'", '4.상세코드'!F15, "'")), ",", '4.상세코드'!G15, ", '", '4.상세코드'!H15, "', '", '4.상세코드'!I15, "'", 상세SQL!C12) | B12: INSERT INTO SM_COMM_D (biz_seq, comm_h_cd, comm_d_cd, comm_d_nm, ref_h_cd, ref_d_cd, disp_no, disp_yn, use_yn, reg_id, reg_dt) VALUES ( | C12: , 'administrator', getDate());
... A4331: =CONCATENATE(B4331, '4.상세코드'!A4334, ", '", '4.상세코드'!B4334, "', '", '4.상세코드'!C4334, "', '", '4.상세코드'!D4334, "',", IF(ISBLANK('4.상세코드'!E4334), "NULL", CONCATENATE("'", '4.상세코드'!E4334, "'")), ",", IF(ISBLANK('4.상세코드'!F4334), "NULL", CONCATENATE("'", '4.상세코드'!F4334, "'")), ",", '4.상세코드'!G4334, ", '", '4.상세코드'!H4334, "', '", '4.상세코드'!I4334, "'", 상세SQL!C4331) | B4331: INSERT INTO SM_COMM_D (biz_seq, comm_h_cd, comm_d_cd, comm_d_nm, ref_h_cd, ref_d_cd, disp_no, disp_yn, use_yn, reg_id, reg_dt) VALUES ( | C4331: , 'administrator', getDate());
