Workbook

Sheet 개발현황
A1: No. | B1: 플랫폼 | C1: 대메뉴 | D1: 메뉴 | F1: 유형 | G1: 개발담당자 | H1: 우선순위 | I1: 완료기한 | J1: 공수(M/D) | L1: 진행율 | M1: 45901 | R1: 45566 | W1: 45597 | AA1: 45627 | AF1: 단테 작성자 | AG1: 공수(M/D) | AI1: 메뉴얼작성자 | AJ1: 공수(M/D)
J2: 계획 | K2: 실적 | M2: 1 | N2: 2 | O2: 3 | P2: 4 | Q2: 5 | R2: 1 | S2: 2 | T2: 3 | U2: 4 | V2: 5 | W2: 1 | X2: 2 | Y2: 3 | Z2: 4 | AA2: 1 | AB2: 2 | AC2: 3 | AD2: 4 | AE2: 5 | AG2: 계획 | AH2: 실적 | AJ2: 계획 | AK2: 실적
A3: 2.3.1 개발- 프로그램 구현 및 개발자 테스트 | J3: =SUM(J4,J19,J39,J52,J83,J95,J104,J134,J146,J150,J159,J168,J172,J182,J189,J201,J206,J214,J220,J224) -> 218.5 | K3: =SUM(K4,K19,K39,K52,K83,K95,K104,K134,K146,K150,K159,K168,K172,K182,K189,K201,K206,K214,K220,K224) -> 218.5 | AG3: =SUM(AG4,AG19,AG39,AG52,AG83,AG95,AG104,AG134,AG146,AG150,AG159,AG168,AG172,AG182,AG189,AG201,AG206,AG214,AG220,AG224) -> 51.3 | AH3: =SUM(AH4,AH19,AH39,AH52,AH83,AH95,AH104,AH134,AH146,AH150,AH159,AH168,AH172,AH182,AH189,AH201,AH206,AH214,AH220,AH224) -> 51.3 | AJ3: =SUM(AJ4,AJ19,AJ39,AJ52,AJ83,AJ95,AJ104,AJ134,AJ146,AJ150,AJ159,AJ168,AJ172,AJ182,AJ189,AJ201,AJ206,AJ214,AJ220,AJ224) -> 51.3 | AK3: =SUM(AK4,AK19,AK39,AK52,AK83,AK95,AK104,AK134,AK146,AK150,AK159,AK168,AK172,AK182,AK189,AK201,AK206,AK214,AK220,AK224) -> 51.3
A4: WEB | C4: 기준정보 | J4: =SUM(J5:J18) -> 8.5 | K4: =SUM(K5:K18) -> 8.5 | AG4: =SUM(AG5:AG18) -> 4.2 | AH4: =SUM(AH5:AH18) -> 4.2 | AJ4: =SUM(AJ5:AJ18) -> 4.2 | AK4: =SUM(AK5:AK18) -> 4.2
A5: 1 | B5: WEB | D5: 사업장 | E5: 조회 | F5: 화면 | G5: 김연수 | I5: 45988 | J5: 0.5 | K5: 0.5 | L5: =K5/J5 -> 1 | M5: 5 | P5: 5 | AA5: 5 | AD5: 5 | AF5: =G5 -> 김연수 | AG5: 0.3 | AH5: 0.3 | AI5: =G5 -> 김연수 | AJ5: 0.3 | AK5: 0.3
A6: 2 | B6: WEB | D6: 창고 | E6: 조회/등록/수정 | F6: 화면 | G6: 김연수 | I6: 45988 | J6: 0.5 | K6: 0.5 | L6: =K6/J6 -> 1 | N6: 4 | O6: 5 | AB6: 4 | AC6: 5 | AF6: =G6 -> 김연수 | AG6: 0.3 | AH6: 0.3 | AI6: =G6 -> 김연수 | AJ6: 0.3 | AK6: 0.3
A7: 3 | B7: WEB | D7: 위치 | E7: 조회/등록/수정 | F7: 화면 | G7: 김연수 | I7: 45988 | J7: 0.5 | K7: 0.5 | L7: =K7/J7 -> 1 | N7: 1 | Q7: 4 | AB7: 1 | AF7: =G7 -> 김연수 | AG7: 0.3 | AH7: 0.3 | AI7: =G7 -> 김연수 | AJ7: 0.3 | AK7: 0.3
A8: 4 | B8: WEB | E8: 엑셀 업로드 | F8: FNC | G8: 김연수 | I8: 45988 | J8: 0.5 | K8: 0.5 | L8: =K8/J8 -> 1 | Q8: 1 | AE8: 1 | AF8: =G8 -> 김연수 | AG8: 0.3 | AH8: 0.3 | AI8: =G8 -> 김연수 | AJ8: 0.3 | AK8: 0.3
A9: 5 | B9: WEB | E9: 라벨출력 | F9: 출력 | G9: 김연수 | I9: 45988 | J9: 0.5 | K9: 0.5 | L9: =K9/J9 -> 1 | R9: 5 | U9: 5 | AF9: =G9 -> 김연수 | AG9: 0.3 | AH9: 0.3 | AI9: =G9 -> 김연수 | AJ9: 0.3 | AK9: 0.3
A10: 6 | B10: WEB | D10: 사용자 | E10: 조회 | F10: 화면 | G10: 김연수 | I10: 45988 | J10: 0.5 | K10: 0.5 | L10: =K10/J10 -> 1 | S10: 4 | T10: 5 | AF10: =G10 -> 김연수 | AG10: 0.3 | AH10: 0.3 | AI10: =G10 -> 김연수 | AJ10: 0.3 | AK10: 0.3
A11: 7 | B11: WEB | E11: 등록/수정 | F11: FNC | G11: 김연수 | I11: 45988 | J11: 0.5 | K11: 0.5 | L11: =K11/J11 -> 1 | S11: 1 | V11: 4 | AF11: =G11 -> 김연수 | AG11: 0.3 | AH11: 0.3 | AI11: =G11 -> 김연수 | AJ11: 0.3 | AK11: 0.3
A12: 8 | B12: WEB | D12: 품목 | E12: 조회 | F12: 화면 | G12: 김연수 | I12: 45988 | J12: 0.5 | K12: 0.5 | L12: =K12/J12 -> 1 | V12: 1 | AF12: =G12 -> 김연수 | AG12: 0.3 | AH12: 0.3 | AI12: =G12 -> 김연수 | AJ12: 0.3 | AK12: 0.3
A13: 9 | B13: WEB | E13: 등록/수정 | F13: 화면 | G13: 김연수 | I13: 45988 | J13: 0.5 | K13: 0.5 | L13: =K13/J13 -> 1 | W13: 5 | Z13: 5 | AF13: =G13 -> 김연수 | AG13: 0.3 | AH13: 0.3 | AI13: =G13 -> 김연수 | AJ13: 0.3 | AK13: 0.3
A14: 10 | B14: WEB | E14: 엑셀 업로드 | F14: FNC | G14: 김연수 | I14: 45988 | J14: 1 | K14: 1 | L14: =K14/J14 -> 1 | X14: 4 | Y14: 5 | AF14: =G14 -> 김연수 | AG14: 0.3 | AH14: 0.3 | AI14: =G14 -> 김연수 | AJ14: 0.3 | AK14: 0.3
A15: 11 | B15: WEB | D15: 거래처 | E15: 조회 | F15: 화면 | G15: 백현주 | I15: 45988 | J15: 1 | K15: 1 | L15: =K15/J15 -> 1 | AF15: =G15 -> 백현주 | AG15: 0.3 | AH15: 0.3 | AI15: =G15 -> 백현주 | AJ15: 0.3 | AK15: 0.3
A16: 12 | B16: WEB | E16: 수정 | F16: FNC | G16: 백현주 | I16: 45988 | J16: 1 | K16: 1 | L16: =K16/J16 -> 1 | AF16: =G16 -> 백현주 | AG16: 0.3 | AH16: 0.3 | AI16: =G16 -> 백현주 | AJ16: 0.3 | AK16: 0.3
A17: 13 | B17: WEB | D17: 세트구성 | E17: 조회 | F17: 화면 | G17: 김연수 | I17: 45988 | J17: 0.5 | K17: 0.5 | L17: =K17/J17 -> 1 | AF17: =G17 -> 김연수 | AG17: 0.3 | AH17: 0.3 | AI17: =G17 -> 김연수 | AJ17: 0.3 | AK17: 0.3
A18: 14 | B18: WEB | E18: 등록/수정 | F18: FNC | G18: 김연수 | I18: 45988 | J18: 0.5 | K18: 0.5 | L18: =K18/J18 -> 1 | AF18: =G18 -> 김연수 | AG18: 0.3 | AH18: 0.3 | AI18: =G18 -> 김연수 | AJ18: 0.3 | AK18: 0.3
A19: WEB | C19: 입고 | J19: =SUM(J20:J38) -> 18 | K19: =SUM(K20:K38) -> 18 | AG19: =SUM(AG20:AG38) -> 5.7 | AH19: =SUM(AH20:AH38) -> 5.7 | AJ19: =SUM(AJ20:AJ38) -> 5.7 | AK19: =SUM(AK20:AK38) -> 5.7
A20: 1 | B20: WEB | D20: 입고예정 | E20: 조회 | F20: 화면 | G20: 백현주 | I20: 45988 | J20: 0.5 | K20: 0.5 | L20: =K20/J20 -> 1 | AF20: =G20 -> 백현주 | AG20: 0.3 | AH20: 0.3 | AI20: =G20 -> 백현주 | AJ20: 0.3 | AK20: 0.3
A21: 2 | B21: WEB | E21: 수정 | F21: FNC | G21: 백현주 | I21: 45988 | J21: 0.5 | K21: 0.5 | L21: =K21/J21 -> 1 | AF21: =G21 -> 백현주 | AG21: 0.3 | AH21: 0.3 | AI21: =G21 -> 백현주 | AJ21: 0.3 | AK21: 0.3
A22: 3 | B22: WEB | D22: 입고처리 | E22: 조회 | F22: 화면 | G22: 백현주 | I22: 45988 | J22: 0.5 | K22: 0.5 | L22: =K22/J22 -> 1 | AF22: =G22 -> 백현주 | AG22: 0.3 | AH22: 0.3 | AI22: =G22 -> 백현주 | AJ22: 0.3 | AK22: 0.3
A23: 4 | B23: WEB | E23: SKU 생성/취소 | F23: FNC | G23: 백현주 | I23: 45988 | J23: 0.5 | K23: 0.5 | L23: =K23/J23 -> 1 | AF23: =G23 -> 백현주 | AG23: 0.3 | AH23: 0.3 | AI23: =G23 -> 백현주 | AJ23: 0.3 | AK23: 0.3
A24: 5 | B24: WEB | E24: SKU 라벨출력 | F24: FNC | G24: 백현주 | I24: 45988 | J24: 0.5 | K24: 0.5 | L24: =K24/J24 -> 1 | AF24: =G24 -> 백현주 | AG24: 0.3 | AH24: 0.3 | AI24: =G24 -> 백현주 | AJ24: 0.3 | AK24: 0.3
A25: 6 | B25: WEB | E25: 입고처리 | F25: FNC | G25: 백현주 | I25: 45988 | J25: 1 | K25: 1 | L25: =K25/J25 -> 1 | AF25: =G25 -> 백현주 | AG25: 0.3 | AH25: 0.3 | AI25: =G25 -> 백현주 | AJ25: 0.3 | AK25: 0.3
A26: 7 | B26: WEB | E26: 가입고처리 | F26: FNC | G26: 백현주 | I26: 45988 | J26: 2 | K26: 2 | L26: =K26/J26 -> 1 | AF26: =G26 -> 백현주 | AG26: 0.3 | AH26: 0.3 | AI26: =G26 -> 백현주 | AJ26: 0.3 | AK26: 0.3
A27: 8 | B27: WEB | E27: 검수 | F27: FNC | G27: 백현주 | I27: 45988 | J27: 2 | K27: 2 | L27: =K27/J27 -> 1 | AF27: =G27 -> 백현주 | AG27: 0.3 | AH27: 0.3 | AI27: =G27 -> 백현주 | AJ27: 0.3 | AK27: 0.3
A28: 9 | B28: WEB | E28: 품목분할 | F28: FNC | G28: 백현주 | I28: 45988 | J28: 1 | K28: 1 | L28: =K28/J28 -> 1 | AF28: =G28 -> 백현주 | AG28: 0.3 | AH28: 0.3 | AI28: =G28 -> 백현주 | AJ28: 0.3 | AK28: 0.3
A29: 10 | B29: WEB | E29: 입고지시서 출력 | F29: 출력 | G29: 백현주 | I29: 45988 | J29: 0.5 | K29: 0.5 | L29: =K29/J29 -> 1 | AF29: =G29 -> 백현주 | AG29: 0.3 | AH29: 0.3 | AI29: =G29 -> 백현주 | AJ29: 0.3 | AK29: 0.3
A30: 11 | B30: WEB | E30: 강제확정 | F30: FNC | G30: 백현주 | I30: 45988 | J30: 0.5 | K30: 0.5 | L30: =K30/J30 -> 1 | AF30: =G30 -> 백현주 | AG30: 0.3 | AH30: 0.3 | AI30: =G30 -> 백현주 | AJ30: 0.3 | AK30: 0.3
A31: 12 | B31: WEB | D31: 입고처리 취소 | E31: 조회 | F31: 화면 | G31: 백현주 | I31: 45988 | J31: 0.5 | K31: 0.5 | L31: =K31/J31 -> 1 | AF31: =G31 -> 백현주 | AG31: 0.3 | AH31: 0.3 | AI31: =G31 -> 백현주 | AJ31: 0.3 | AK31: 0.3
A32: 13 | B32: WEB | E32: 처리취소 | F32: FNC | G32: 백현주 | I32: 45988 | J32: 2 | K32: 2 | L32: =K32/J32 -> 1 | AF32: =G32 -> 백현주 | AG32: 0.3 | AH32: 0.3 | AI32: =G32 -> 백현주 | AJ32: 0.3 | AK32: 0.3
A33: 14 | B33: WEB | E33: 검수취소 | F33: FNC | G33: 백현주 | I33: 45988 | J33: 1 | K33: 1 | L33: =K33/J33 -> 1 | AF33: =G33 -> 백현주 | AG33: 0.3 | AH33: 0.3 | AI33: =G33 -> 백현주 | AJ33: 0.3 | AK33: 0.3
A34: 15 | B34: WEB | D34: 입고마감 | E34: 조회 | F34: 화면 | G34: 이영진 | I34: 45988 | J34: 1 | K34: 1 | L34: =K34/J34 -> 1 | AF34: =G34 -> 이영진 | AG34: 0.3 | AH34: 0.3 | AI34: =G34 -> 이영진 | AJ34: 0.3 | AK34: 0.3
A35: 16 | B35: WEB | E35: 마감처리 | F35: FNC | G35: 이영진 | I35: 45988 | J35: 1 | K35: 1 | L35: =K35/J35 -> 1 | AF35: =G35 -> 이영진 | AG35: 0.3 | AH35: 0.3 | AI35: =G35 -> 이영진 | AJ35: 0.3 | AK35: 0.3
A36: 17 | B36: WEB | D36: 입고현황 | E36: 조회 | F36: 화면 | G36: 이영진 | I36: 45988 | J36: 0.5 | K36: 0.5 | L36: =K36/J36 -> 1 | AF36: =G36 -> 이영진 | AG36: 0.3 | AH36: 0.3 | AI36: =G36 -> 이영진 | AJ36: 0.3 | AK36: 0.3
A37: 18 | B37: WEB | E37: 축산이력번호 등록 | F37: FNC | G37: 이영진 | I37: 45988 | J37: 2 | K37: 2 | L37: =K37/J37 -> 1 | AF37: =G37 -> 이영진 | AG37: 0.3 | AH37: 0.3 | AI37: =G37 -> 이영진 | AJ37: 0.3 | AK37: 0.3
A38: 19 | B38: WEB | E38: 엑셀 다운로드 | F38: FNC | G38: 이영진 | I38: 45988 | J38: 0.5 | K38: 0.5 | L38: =K38/J38 -> 1 | AF38: =G38 -> 이영진 | AG38: 0.3 | AH38: 0.3 | AI38: =G38 -> 이영진 | AJ38: 0.3 | AK38: 0.3
A39: WEB | C39: 반품 | I39: =SUM(I84:I94) -> 10 | J39: =SUM(J40:J51) -> 6 | K39: =SUM(K40:K51) -> 6 | AG39: =SUM(AG40:AG51) -> 3.6 | AH39: =SUM(AH40:AH51) -> 3.6 | AJ39: =SUM(AJ40:AJ51) -> 3.6 | AK39: =SUM(AK40:AK51) -> 3.6
A40: 1 | B40: WEB | D40: 반품예정 | E40: 조회 | F40: 화면 | G40: 이영진 | I40: 45988 | J40: 0.5 | K40: 0.5 | L40: =K40/J40 -> 1 | AF40: =G40 -> 이영진 | AG40: 0.3 | AH40: 0.3 | AI40: =G40 -> 이영진 | AJ40: 0.3 | AK40: 0.3
...

Sheet 담당자별공수
M1: 5 | N1: 5 | O1: 5 | P1: 5 | Q1: 2 | R1: 2 | S1: 1 | T1: 5 | U1: 5 | V1: 5 | W1: 5 | X1: 5 | Y1: 5 | Z1: 5 | AA1: 5 | AB1: 5 | AC1: 5 | AD1: 4 | AE1: 3 | AF1: 작업일수
M2: 45901 | R2: 45931 | W2: 45962 | AA2: 45992
A3: 인원별 공수(개발) | M3: 1 | N3: 2 | O3: 3 | P3: 4 | Q3: 5 | R3: 1 | S3: 2 | T3: 3 | U3: 4 | V3: 5 | W3: 1 | X3: 2 | Y3: 3 | Z3: 4 | AA3: 1 | AB3: 2 | AC3: 3 | AD3: 4 | AE3: 5
A4: 김연수 | B4: =SUMIF(개발현황!G5:G300,A4,개발현황!J5:J300) -> 63.5 | M4: =SUMIF(개발현황!G5:G300,A4,개발현황!M5:M300) -> 5 | N4: =SUMIF(개발현황!G5:G300,A4,개발현황!N5:N300) -> 5 | O4: =SUMIF(개발현황!G5:G300,A4,개발현황!O5:O300) -> 5 | P4: =SUMIF(개발현황!G5:G300,A4,개발현황!P5:P300) -> 5 | Q4: =SUMIF(개발현황!G5:G300,A4,개발현황!Q5:Q300) -> 5 | R4: =SUMIF(개발현황!G5:G300,A4,개발현황!R5:R300) -> 5 | S4: =SUMIF(개발현황!G5:G300,A4,개발현황!S5:S300) -> 5 | T4: =SUMIF(개발현황!G5:G300,A4,개발현황!T5:T300) -> 5 | U4: =SUMIF(개발현황!G5:G300,A4,개발현황!U5:U300) -> 5 | V4: =SUMIF(개발현황!G5:G300,A4,개발현황!V5:V300) -> 5 | W4: =SUMIF(개발현황!G5:G300,A4,개발현황!W5:W300) -> 5 | X4: =SUMIF(개발현황!G5:G300,A4,개발현황!X5:X300) -> 4 | Y4: =SUMIF(개발현황!G5:G300,A4,개발현황!Y5:Y300) -> 5 | Z4: =SUMIF(개발현황!G5:G300,A4,개발현황!Z5:Z300) -> 5 | AA4: =SUMIF(개발현황!G5:G300,A4,개발현황!AA5:AA300) -> 5 | AB4: =SUMIF(개발현황!G5:G300,A4,개발현황!AB5:AB300) -> 5 | AC4: =SUMIF(개발현황!G5:G300,A4,개발현황!AC5:AC300) -> 5 | AD4: =SUMIF(개발현황!G5:G300,A4,개발현황!AD5:AD300) -> 5 | AE4: =SUMIF(개발현황!G5:G300,A4,개발현황!AE5:AE300) -> 1 | AF4: =SUM(M4:AE4) -> 90
A5: 백현주 | B5: =SUMIF(개발현황!G5:G300,A5,개발현황!J5:J300) -> 33.5 | M5: =SUMIF(개발현황!G6:G301,A5,개발현황!M6:M301) -> 0 | N5: =SUMIF(개발현황!G6:G301,A5,개발현황!N6:N301) -> 0 | O5: =SUMIF(개발현황!G6:G301,A5,개발현황!O6:O301) -> 0 | P5: =SUMIF(개발현황!G6:G301,A5,개발현황!P6:P301) -> 0 | Q5: =SUMIF(개발현황!G6:G301,A5,개발현황!Q6:Q301) -> 0 | R5: =SUMIF(개발현황!G6:G301,A5,개발현황!R6:R301) -> 0 | S5: =SUMIF(개발현황!G6:G301,A5,개발현황!S6:S301) -> 0 | T5: =SUMIF(개발현황!G6:G301,A5,개발현황!T6:T301) -> 0 | U5: =SUMIF(개발현황!G6:G301,A5,개발현황!U6:U301) -> 0 | V5: =SUMIF(개발현황!G6:G301,A5,개발현황!V6:V301) -> 0 | W5: =SUMIF(개발현황!G6:G301,A5,개발현황!W6:W301) -> 0 | X5: =SUMIF(개발현황!G6:G301,A5,개발현황!X6:X301) -> 0 | Y5: =SUMIF(개발현황!G6:G301,A5,개발현황!Y6:Y301) -> 0 | Z5: =SUMIF(개발현황!G6:G301,A5,개발현황!Z6:Z301) -> 0 | AA5: =SUMIF(개발현황!G6:G301,A5,개발현황!AA6:AA301) -> 0 | AB5: =SUMIF(개발현황!G6:G301,A5,개발현황!AB6:AB301) -> 0 | AC5: =SUMIF(개발현황!G6:G301,A5,개발현황!AC6:AC301) -> 0 | AD5: =SUMIF(개발현황!G6:G301,A5,개발현황!AD6:AD301) -> 0 | AE5: =SUMIF(개발현황!G6:G301,A5,개발현황!AE6:AE301) -> 0 | AF5: =SUM(M5:AE5) -> 0
A6: 이영진 | B6: =SUMIF(개발현황!G5:G300,A6,개발현황!J5:J300) -> 18 | M6: =SUMIF(개발현황!G7:G302,A6,개발현황!M7:M302) -> 0 | N6: =SUMIF(개발현황!G7:G302,A6,개발현황!N7:N302) -> 0 | O6: =SUMIF(개발현황!G7:G302,A6,개발현황!O7:O302) -> 0 | P6: =SUMIF(개발현황!G7:G302,A6,개발현황!P7:P302) -> 0 | Q6: =SUMIF(개발현황!G7:G302,A6,개발현황!Q7:Q302) -> 0 | R6: =SUMIF(개발현황!G7:G302,A6,개발현황!R7:R302) -> 0 | S6: =SUMIF(개발현황!G7:G302,A6,개발현황!S7:S302) -> 0 | T6: =SUMIF(개발현황!G7:G302,A6,개발현황!T7:T302) -> 0 | U6: =SUMIF(개발현황!G7:G302,A6,개발현황!U7:U302) -> 0 | V6: =SUMIF(개발현황!G7:G302,A6,개발현황!V7:V302) -> 0 | W6: =SUMIF(개발현황!G7:G302,A6,개발현황!W7:W302) -> 0 | X6: =SUMIF(개발현황!G7:G302,A6,개발현황!X7:X302) -> 0 | Y6: =SUMIF(개발현황!G7:G302,A6,개발현황!Y7:Y302) -> 0 | Z6: =SUMIF(개발현황!G7:G302,A6,개발현황!Z7:Z302) -> 0 | AA6: =SUMIF(개발현황!G7:G302,A6,개발현황!AA7:AA302) -> 0 | AB6: =SUMIF(개발현황!G7:G302,A6,개발현황!AB7:AB302) -> 0 | AC6: =SUMIF(개발현황!G7:G302,A6,개발현황!AC7:AC302) -> 0 | AD6: =SUMIF(개발현황!G7:G302,A6,개발현황!AD7:AD302) -> 0 | AE6: =SUMIF(개발현황!G7:G302,A6,개발현황!AE7:AE302) -> 0 | AF6: =SUM(M6:AE6) -> 0
A7: 유형기 | B7: =SUMIF(개발현황!G5:G300,A7,개발현황!J5:J300) -> 8 | M7: =SUMIF(개발현황!G8:G303,A7,개발현황!M8:M303) -> 0 | N7: =SUMIF(개발현황!G8:G303,A7,개발현황!N8:N303) -> 0 | O7: =SUMIF(개발현황!G8:G303,A7,개발현황!O8:O303) -> 0 | P7: =SUMIF(개발현황!G8:G303,A7,개발현황!P8:P303) -> 0 | Q7: =SUMIF(개발현황!G8:G303,A7,개발현황!Q8:Q303) -> 0 | R7: =SUMIF(개발현황!G8:G303,A7,개발현황!R8:R303) -> 0 | S7: =SUMIF(개발현황!G8:G303,A7,개발현황!S8:S303) -> 0 | T7: =SUMIF(개발현황!G8:G303,A7,개발현황!T8:T303) -> 0 | U7: =SUMIF(개발현황!G8:G303,A7,개발현황!U8:U303) -> 0 | V7: =SUMIF(개발현황!G8:G303,A7,개발현황!V8:V303) -> 0 | W7: =SUMIF(개발현황!G8:G303,A7,개발현황!W8:W303) -> 0 | X7: =SUMIF(개발현황!G8:G303,A7,개발현황!X8:X303) -> 0 | Y7: =SUMIF(개발현황!G8:G303,A7,개발현황!Y8:Y303) -> 0 | Z7: =SUMIF(개발현황!G8:G303,A7,개발현황!Z8:Z303) -> 0 | AA7: =SUMIF(개발현황!G8:G303,A7,개발현황!AA8:AA303) -> 0 | AB7: =SUMIF(개발현황!G8:G303,A7,개발현황!AB8:AB303) -> 0 | AC7: =SUMIF(개발현황!G8:G303,A7,개발현황!AC8:AC303) -> 0 | AD7: =SUMIF(개발현황!G8:G303,A7,개발현황!AD8:AD303) -> 0 | AE7: =SUMIF(개발현황!G8:G303,A7,개발현황!AE8:AE303) -> 0 | AF7: =SUM(M7:AE7) -> 0
A8: 김정훈 | B8: =SUMIF(개발현황!G5:G300,A8,개발현황!J5:J300) -> 38.5 | M8: =SUMIF(개발현황!G9:G304,A8,개발현황!M9:M304) -> 0 | N8: =SUMIF(개발현황!G9:G304,A8,개발현황!N9:N304) -> 0 | O8: =SUMIF(개발현황!G9:G304,A8,개발현황!O9:O304) -> 0 | P8: =SUMIF(개발현황!G9:G304,A8,개발현황!P9:P304) -> 0 | Q8: =SUMIF(개발현황!G9:G304,A8,개발현황!Q9:Q304) -> 0 | R8: =SUMIF(개발현황!G9:G304,A8,개발현황!R9:R304) -> 0 | S8: =SUMIF(개발현황!G9:G304,A8,개발현황!S9:S304) -> 0 | T8: =SUMIF(개발현황!G9:G304,A8,개발현황!T9:T304) -> 0 | U8: =SUMIF(개발현황!G9:G304,A8,개발현황!U9:U304) -> 0 | V8: =SUMIF(개발현황!G9:G304,A8,개발현황!V9:V304) -> 0 | W8: =SUMIF(개발현황!G9:G304,A8,개발현황!W9:W304) -> 0 | X8: =SUMIF(개발현황!G9:G304,A8,개발현황!X9:X304) -> 0 | Y8: =SUMIF(개발현황!G9:G304,A8,개발현황!Y9:Y304) -> 0 | Z8: =SUMIF(개발현황!G9:G304,A8,개발현황!Z9:Z304) -> 0 | AA8: =SUMIF(개발현황!G9:G304,A8,개발현황!AA9:AA304) -> 0 | AB8: =SUMIF(개발현황!G9:G304,A8,개발현황!AB9:AB304) -> 0 | AC8: =SUMIF(개발현황!G9:G304,A8,개발현황!AC9:AC304) -> 0 | AD8: =SUMIF(개발현황!G9:G304,A8,개발현황!AD9:AD304) -> 0 | AE8: =SUMIF(개발현황!G9:G304,A8,개발현황!AE9:AE304) -> 0 | AF8: =SUM(M8:AE8) -> 0
A9: 왕예빈 | B9: =SUMIF(개발현황!G5:G300,A9,개발현황!J5:J300) -> 47 | M9: =SUMIF(개발현황!G10:G305,A9,개발현황!M10:M305) -> 0 | N9: =SUMIF(개발현황!G10:G305,A9,개발현황!N10:N305) -> 0 | O9: =SUMIF(개발현황!G10:G305,A9,개발현황!O10:O305) -> 0 | P9: =SUMIF(개발현황!G10:G305,A9,개발현황!P10:P305) -> 0 | Q9: =SUMIF(개발현황!G10:G305,A9,개발현황!Q10:Q305) -> 0 | R9: =SUMIF(개발현황!G10:G305,A9,개발현황!R10:R305) -> 0 | S9: =SUMIF(개발현황!G10:G305,A9,개발현황!S10:S305) -> 0 | T9: =SUMIF(개발현황!G10:G305,A9,개발현황!T10:T305) -> 0 | U9: =SUMIF(개발현황!G10:G305,A9,개발현황!U10:U305) -> 0 | V9: =SUMIF(개발현황!G10:G305,A9,개발현황!V10:V305) -> 0 | W9: =SUMIF(개발현황!G10:G305,A9,개발현황!W10:W305) -> 0 | X9: =SUMIF(개발현황!G10:G305,A9,개발현황!X10:X305) -> 0 | Y9: =SUMIF(개발현황!G10:G305,A9,개발현황!Y10:Y305) -> 0 | Z9: =SUMIF(개발현황!G10:G305,A9,개발현황!Z10:Z305) -> 0 | AA9: =SUMIF(개발현황!G10:G305,A9,개발현황!AA10:AA305) -> 0 | AB9: =SUMIF(개발현황!G10:G305,A9,개발현황!AB10:AB305) -> 0 | AC9: =SUMIF(개발현황!G10:G305,A9,개발현황!AC10:AC305) -> 0 | AD9: =SUMIF(개발현황!G10:G305,A9,개발현황!AD10:AD305) -> 0 | AE9: =SUMIF(개발현황!G10:G305,A9,개발현황!AE10:AE305) -> 0 | AF9: =SUM(M9:AE9) -> 0
A10: 이은복 | B10: =SUMIF(개발현황!G5:G300,A10,개발현황!J5:J300) -> 7.5 | M10: =SUMIF(개발현황!G11:G306,A10,개발현황!M11:M306) -> 0 | N10: =SUMIF(개발현황!G11:G306,A10,개발현황!N11:N306) -> 0 | O10: =SUMIF(개발현황!G11:G306,A10,개발현황!O11:O306) -> 0 | P10: =SUMIF(개발현황!G11:G306,A10,개발현황!P11:P306) -> 0 | Q10: =SUMIF(개발현황!G11:G306,A10,개발현황!Q11:Q306) -> 0 | R10: =SUMIF(개발현황!G11:G306,A10,개발현황!R11:R306) -> 0 | S10: =SUMIF(개발현황!G11:G306,A10,개발현황!S11:S306) -> 0 | T10: =SUMIF(개발현황!G11:G306,A10,개발현황!T11:T306) -> 0 | U10: =SUMIF(개발현황!G11:G306,A10,개발현황!U11:U306) -> 0 | V10: =SUMIF(개발현황!G11:G306,A10,개발현황!V11:V306) -> 0 | W10: =SUMIF(개발현황!G11:G306,A10,개발현황!W11:W306) -> 0 | X10: =SUMIF(개발현황!G11:G306,A10,개발현황!X11:X306) -> 0 | Y10: =SUMIF(개발현황!G11:G306,A10,개발현황!Y11:Y306) -> 0 | Z10: =SUMIF(개발현황!G11:G306,A10,개발현황!Z11:Z306) -> 0 | AA10: =SUMIF(개발현황!G11:G306,A10,개발현황!AA11:AA306) -> 0 | AB10: =SUMIF(개발현황!G11:G306,A10,개발현황!AB11:AB306) -> 0 | AC10: =SUMIF(개발현황!G11:G306,A10,개발현황!AC11:AC306) -> 0 | AD10: =SUMIF(개발현황!G11:G306,A10,개발현황!AD11:AD306) -> 0 | AE10: =SUMIF(개발현황!G11:G306,A10,개발현황!AE11:AE306) -> 0 | AF10: =SUM(M10:AE10) -> 0
A11: 전민주 | B11: =SUMIF(개발현황!G5:G300,A11,개발현황!J5:J300) -> 2.5 | M11: =SUMIF(개발현황!G12:G307,A11,개발현황!M12:M307) -> 0 | N11: =SUMIF(개발현황!G12:G307,A11,개발현황!N12:N307) -> 0 | O11: =SUMIF(개발현황!G12:G307,A11,개발현황!O12:O307) -> 0 | P11: =SUMIF(개발현황!G12:G307,A11,개발현황!P12:P307) -> 0 | Q11: =SUMIF(개발현황!G12:G307,A11,개발현황!Q12:Q307) -> 0 | R11: =SUMIF(개발현황!G12:G307,A11,개발현황!R12:R307) -> 0 | S11: =SUMIF(개발현황!G12:G307,A11,개발현황!S12:S307) -> 0 | T11: =SUMIF(개발현황!G12:G307,A11,개발현황!T12:T307) -> 0 | U11: =SUMIF(개발현황!G12:G307,A11,개발현황!U12:U307) -> 0 | V11: =SUMIF(개발현황!G12:G307,A11,개발현황!V12:V307) -> 0 | W11: =SUMIF(개발현황!G12:G307,A11,개발현황!W12:W307) -> 0 | X11: =SUMIF(개발현황!G12:G307,A11,개발현황!X12:X307) -> 0 | Y11: =SUMIF(개발현황!G12:G307,A11,개발현황!Y12:Y307) -> 0 | Z11: =SUMIF(개발현황!G12:G307,A11,개발현황!Z12:Z307) -> 0 | AA11: =SUMIF(개발현황!G12:G307,A11,개발현황!AA12:AA307) -> 0 | AB11: =SUMIF(개발현황!G12:G307,A11,개발현황!AB12:AB307) -> 0 | AC11: =SUMIF(개발현황!G12:G307,A11,개발현황!AC12:AC307) -> 0 | AD11: =SUMIF(개발현황!G12:G307,A11,개발현황!AD12:AD307) -> 0 | AE11: =SUMIF(개발현황!G12:G307,A11,개발현황!AE12:AE307) -> 0 | AF11: =SUM(M11:AE11) -> 0
B12: =SUMIF(개발현황!G13:G207,A12,개발현황!J13:J207) -> 0 | M12: =SUMIF(개발현황!G13:G308,A12,개발현황!M13:M308) -> 0 | N12: =SUMIF(개발현황!G13:G308,A12,개발현황!N13:N308) -> 0 | O12: =SUMIF(개발현황!G13:G308,A12,개발현황!O13:O308) -> 0 | P12: =SUMIF(개발현황!G13:G308,A12,개발현황!P13:P308) -> 0 | Q12: =SUMIF(개발현황!G13:G308,A12,개발현황!Q13:Q308) -> 0 | R12: =SUMIF(개발현황!G13:G308,A12,개발현황!R13:R308) -> 0 | S12: =SUMIF(개발현황!G13:G308,A12,개발현황!S13:S308) -> 0 | T12: =SUMIF(개발현황!G13:G308,A12,개발현황!T13:T308) -> 0 | U12: =SUMIF(개발현황!G13:G308,A12,개발현황!U13:U308) -> 0 | V12: =SUMIF(개발현황!G13:G308,A12,개발현황!V13:V308) -> 0 | W12: =SUMIF(개발현황!G13:G308,A12,개발현황!W13:W308) -> 0 | X12: =SUMIF(개발현황!G13:G308,A12,개발현황!X13:X308) -> 0 | Y12: =SUMIF(개발현황!G13:G308,A12,개발현황!Y13:Y308) -> 0 | Z12: =SUMIF(개발현황!G13:G308,A12,개발현황!Z13:Z308) -> 0 | AA12: =SUMIF(개발현황!G13:G308,A12,개발현황!AA13:AA308) -> 0 | AB12: =SUMIF(개발현황!G13:G308,A12,개발현황!AB13:AB308) -> 0 | AC12: =SUMIF(개발현황!G13:G308,A12,개발현황!AC13:AC308) -> 0 | AD12: =SUMIF(개발현황!G13:G308,A12,개발현황!AD13:AD308) -> 0 | AE12: =SUMIF(개발현황!G13:G308,A12,개발현황!AE13:AE308) -> 0 | AF12: =SUM(M12:AE12) -> 0
B13: =SUMIF(개발현황!G14:G208,A13,개발현황!J14:J208) -> 0 | M13: =SUMIF(개발현황!G14:G309,A13,개발현황!M14:M309) -> 0 | N13: =SUMIF(개발현황!G14:G309,A13,개발현황!N14:N309) -> 0 | O13: =SUMIF(개발현황!G14:G309,A13,개발현황!O14:O309) -> 0 | P13: =SUMIF(개발현황!G14:G309,A13,개발현황!P14:P309) -> 0 | Q13: =SUMIF(개발현황!G14:G309,A13,개발현황!Q14:Q309) -> 0 | R13: =SUMIF(개발현황!G14:G309,A13,개발현황!R14:R309) -> 0 | S13: =SUMIF(개발현황!G14:G309,A13,개발현황!S14:S309) -> 0 | T13: =SUMIF(개발현황!G14:G309,A13,개발현황!T14:T309) -> 0 | U13: =SUMIF(개발현황!G14:G309,A13,개발현황!U14:U309) -> 0 | V13: =SUMIF(개발현황!G14:G309,A13,개발현황!V14:V309) -> 0 | W13: =SUMIF(개발현황!G14:G309,A13,개발현황!W14:W309) -> 0 | X13: =SUMIF(개발현황!G14:G309,A13,개발현황!X14:X309) -> 0 | Y13: =SUMIF(개발현황!G14:G309,A13,개발현황!Y14:Y309) -> 0 | Z13: =SUMIF(개발현황!G14:G309,A13,개발현황!Z14:Z309) -> 0 | AA13: =SUMIF(개발현황!G14:G309,A13,개발현황!AA14:AA309) -> 0 | AB13: =SUMIF(개발현황!G14:G309,A13,개발현황!AB14:AB309) -> 0 | AC13: =SUMIF(개발현황!G14:G309,A13,개발현황!AC14:AC309) -> 0 | AD13: =SUMIF(개발현황!G14:G309,A13,개발현황!AD14:AD309) -> 0 | AE13: =SUMIF(개발현황!G14:G309,A13,개발현황!AE14:AE309) -> 0 | AF13: =SUM(M13:AE13) -> 0
M14: =SUM(M4:M13) -> 5 | N14: =SUM(N4:N13) -> 5 | O14: =SUM(O4:O13) -> 5 | P14: =SUM(P4:P13) -> 5 | Q14: =SUM(Q4:Q13) -> 5 | R14: =SUM(R4:R13) -> 5 | S14: =SUM(S4:S13) -> 5 | T14: =SUM(T4:T13) -> 5 | ... AE14: =SUM(AE4:AE13) -> 1

Sheet 진행상황
A1: 항목 | B1: 계획 | C1: 완료 | D1: 진행율
A2: 2.3.1. 프로그램구현 및 개발자 테스트 | B2: =개발현황!J3 -> 218.5 | C2: =개발현황!K3 -> 218.5 | D2: =C2/B2 -> 1
A3: 2.3.2 단위테스트 | B3: =개발현황!AG3 -> 51.3 | C3: =개발현황!AH3 -> 51.3 | D3: =C3/B3 -> 1
A4: 2.3.3 매뉴얼 작성 | B4: =개발현황!AJ3 -> 51.3 | C4: =개발현황!AK3 -> 51.3 | D4: =C4/B4 -> 1
A5: 총 개발공수(M/D) | B5: =B2+B3+B4 -> 321.1 | C5: =C2+C3+C4 -> 321.1 | D5: =C5/B5 -> 1
